Workbook
Name 被评估单位: 设定信息!$B$6
Name 评估基准日: 设定信息!$B$7

Sheet 目录
A2: 0-其他方法结论 | C2: 0-其他方法结论 | L2: 23 | M2: 9
A3: 1-汇总表 | C3: 资产评估结果汇总表 | L3: 31 | M3: 7
A4: 2-分类汇总 | C4: 资产评估结果分类汇总表 | L4: 65 | M4: 7
A5: 3-流动资产汇总 | C5: 流动资产评估汇总表 | L5: 26 | M5: 7
A6: 3-辅-流动资产汇总 | C6: 流动资产余额评估汇总表 | L6: 30 | M6: 7
A7: 3-1货币资金汇总表 | C7: 货币资金评估汇总表 | L7: 23 | M7: 8
A8: 3-1-1现金 | C8: 货币资金—现金评估明细表 | L8: 5 | M8: 10
A9: 3-1-2银行存款 | C9: 货币资金—银行存款评估明细表 | L9: 5 | M9: 11
A10: 3-1-3其他货币资金 | C10: 货币资金—其他货币资金评估明细表 | L10: 5 | M10: 11
A11: 3-2交易性金融资产汇总 | C11: 交易性金融资产评估汇总表 | L11: 24 | M11: 7
A12: 3-2-1-股票 | C12: 交易性金融资产—股票投资评估明细表 | L12: 5 | M12: 12
A13: 3-2-2-债券 | C13: 交易性金融资产—债券投资评估明细表 | L13: 5 | M13: 12
... A105: 9-非财务信息汇总表 | C105: 非财务信息汇总表 | L105: 100 | M105: 7

Sheet 0-报告用表
F2: 单位：万元 | K2: 单位：元
B3: 项 目 | C3: 账面价值 | D3: 评估价值 | E3: 增值额 | F3: 增值率% | I3: 资产项目 | J3: 账面原值 | K3: 账面净值
C4: A | D4: B | E4: C=B-A | F4: D=C/A×100 | I4: 流动资产 | K4: =IF('2-分类汇总'!E6="","",'2-分类汇总'!E6)
B5: 流动资产 | C5: =IF('1-汇总表'!E7="","",ROUND('1-汇总表'!E7,2)) | D5: =IF('1-汇总表'!F7="","",ROUND('1-汇总表'!F7,2)) | E5: =IF('1-汇总表'!G7="","",ROUND('1-汇总表'!G7,2)) | F5: =IF('1-汇总表'!H7="","",ROUND('1-汇总表'!H7,2)) | I5: 存货 | K5: =IF('2-分类汇总'!E15="","",ROUND('2-分类汇总'!E15,2))
B6: 存货 | C6: =IF('2-分类汇总'!E15="","",ROUND('2-分类汇总'!E15/10000,2)) | D6: =IF('2-分类汇总'!F15="","",ROUND('2-分类汇总'!F15/10000,2)) | E6: =IF('2-分类汇总'!G15="","",ROUND('2-分类汇总'!G15/10000,2)) | F6: =IF('2-分类汇总'!H15="","",ROUND('2-分类汇总'!H15,2)) | I6: 非流动资产 | K6: =IF('2-分类汇总'!E20="","",ROUND('2-分类汇总'!E20,2))
B7: 非流动资产 | C7: =IF('1-汇总表'!E8="","",ROUND('1-汇总表'!E8,2)) | D7: =IF('1-汇总表'!F8="","",ROUND('1-汇总表'!F8,2)) | E7: =IF('1-汇总表'!G8="","",ROUND('1-汇总表'!G8,2)) | F7: =IF('1-汇总表'!H8="","",ROUND('1-汇总表'!H8,2)) | I7: 长期股权投资 | K7: =IF('2-分类汇总'!E24="","",ROUND('2-分类汇总'!E24,2))
B8: 长期股权投资 | C8: =IF('1-汇总表'!E12="","",ROUND('1-汇总表'!E12,2)) | D8: =IF('1-汇总表'!F12="","",ROUND('1-汇总表'!F12,2)) | E8: =IF('1-汇总表'!G12="","",ROUND('1-汇总表'!G12,2)) | F8: =IF('1-汇总表'!H12="","",ROUND('1-汇总表'!H12,2)) | I8: 投资性房地产 | K8: =IF('2-分类汇总'!E27="","",ROUND('2-分类汇总'!E27,2))
B9: 投资性房地产 | C9: =IF('1-汇总表'!E15="","",ROUND('1-汇总表'!E15,2)) | D9: =IF('1-汇总表'!F15="","",ROUND('1-汇总表'!F15,2)) | E9: =IF('1-汇总表'!G15="","",ROUND('1-汇总表'!G15,2)) | F9: =IF('1-汇总表'!H15="","",ROUND('1-汇总表'!H15,2)) | I9: 固定资产 | J9: =IF('4-8固定资产汇总'!E20="","",ROUND('4-8固定资产汇总'!E20,2)) | K9: =IF('2-分类汇总'!E28="","",ROUND('2-分类汇总'!E28,2))
B10: 固定资产 | C10: =IF('1-汇总表'!E16="","",ROUND('1-汇总表'!E16,2)) | D10: =IF('1-汇总表'!F16="","",ROUND('1-汇总表'!F16,2)) | E10: =IF('1-汇总表'!G16="","",ROUND('1-汇总表'!G16,2)) | F10: =IF('1-汇总表'!H16="","",ROUND('1-汇总表'!H16,2)) | I10: 其中：建筑物类 | J10: =IF('4-8固定资产汇总'!E10="","",ROUND('4-8固定资产汇总'!E10,2)) | K10: =IF('4-8固定资产汇总'!F10="","",ROUND('4-8固定资产汇总'!F10,2))
B11: 其中：建筑物类 | C11: =IF('4-8固定资产汇总'!F10="","",ROUND('4-8固定资产汇总'!F10/10000,2)) | D11: =IF('4-8固定资产汇总'!H10="","",ROUND('4-8固定资产汇总'!H10/10000,2)) | E11: =IF('4-8固定资产汇总'!J10="","",ROUND('4-8固定资产汇总'!J10/10000,2)) | F11: =IF('4-8固定资产汇总'!L9="","",ROUND('4-8固定资产汇总'!L9,2)) | I11: 设备类 | J11: =IF('4-8固定资产汇总'!E16="","",ROUND('4-8固定资产汇总'!E16,2)) | K11: =IF('4-8固定资产汇总'!F16="","",ROUND('4-8固定资产汇总'!F16,2))
B12: 设备类 | C12: =IF('4-8固定资产汇总'!F16="","",ROUND('4-8固定资产汇总'!F16/10000,2)) | D12: =IF('4-8固定资产汇总'!H16="","",ROUND('4-8固定资产汇总'!H16/10000,2)) | E12: =IF('4-8固定资产汇总'!J16="","",ROUND('4-8固定资产汇总'!J16/10000,2)) | F12: =IF('4-8固定资产汇总'!L16="","",ROUND('4-8固定资产汇总'!L16,2)) | I12: 在建工程 | K12: =IF('2-分类汇总'!E29="","",ROUND('2-分类汇总'!E29,2))
B13: 在建工程 | C13: =IF('1-汇总表'!E17="","",ROUND('1-汇总表'!E17,2)) | D13: =IF('1-汇总表'!F17="","",ROUND('1-汇总表'!F17,2)) | E13: =IF('1-汇总表'!G17="","",ROUND('1-汇总表'!G17,2)) | F13: =IF('1-汇总表'!H17="","",ROUND('1-汇总表'!H17,2)) | I13: 无形资产 | K13: =IF('2-分类汇总'!E33="","",ROUND('2-分类汇总'!E33,2))
B14: 无形资产 | C14: =IF('1-汇总表'!E21="","",ROUND('1-汇总表'!E21,2)) | D14: =IF('1-汇总表'!F21="","",ROUND('1-汇总表'!F21,2)) | E14: =IF('1-汇总表'!G21="","",ROUND('1-汇总表'!G21,2)) | F14: =IF('1-汇总表'!H21="","",ROUND('1-汇总表'!H21,2)) | I14: 其中：土地使用权 | J14: =IF('4-13-1无形-土地'!L30="","",ROUND('4-13-1无形-土地'!L30,2)) | K14: =IF('4-13无形资产汇总'!E6="","",ROUND('4-13无形资产汇总'!E6,2))
B15: 其中：土地使用权 | C15: =IF('4-13无形资产汇总'!E6="","",ROUND('4-13无形资产汇总'!E6/10000,2)) | D15: =IF('4-13无形资产汇总'!F6="","",ROUND('4-13无形资产汇总'!F6/10000,2)) | E15: =IF('4-13无形资产汇总'!G6="","",ROUND('4-13无形资产汇总'!G6/10000,2)) | F15: =IF('4-13无形资产汇总'!H6="","",ROUND('4-13无形资产汇总'!H6,2)) | I15: 长期待摊费用 | K15: =IF('2-分类汇总'!E36="","",ROUND('2-分类汇总'!E36,2))
B16: 长期待摊费用 | C16: =IF('1-汇总表'!E24="","",ROUND('1-汇总表'!E24,2)) | D16: =IF('1-汇总表'!F24="","",ROUND('1-汇总表'!F24,2)) | E16: =IF('1-汇总表'!G24="","",ROUND('1-汇总表'!G24,2)) | F16: =IF('1-汇总表'!H24="","",ROUND('1-汇总表'!H24,2)) | I16: 递延所得税资产 | K16: =IF('2-分类汇总'!E37="","",ROUND('2-分类汇总'!E37,2))
B17: 递延所得税资产 | C17: =IF('1-汇总表'!E25="","",ROUND('1-汇总表'!E25,2)) | D17: =IF('1-汇总表'!F25="","",ROUND('1-汇总表'!F25,2)) | E17: =IF('1-汇总表'!G25="","",ROUND('1-汇总表'!G25,2)) | F17: =IF('1-汇总表'!H25="","",ROUND('1-汇总表'!H25,2)) | I17: 其他非流动资产 | K17: =IF('2-分类汇总'!E38="","",ROUND('2-分类汇总'!E38,2))
B18: 其他非流动资产 | C18: =IF('1-汇总表'!E26="","",ROUND('1-汇总表'!E26,2)) | D18: =IF('1-汇总表'!F26="","",ROUND('1-汇总表'!F26,2)) | E18: =IF('1-汇总表'!G26="","",ROUND('1-汇总表'!G26,2)) | F18: =IF('1-汇总表'!H26="","",ROUND('1-汇总表'!H26,2)) | I18: 资产总计 | K18: =IF('2-分类汇总'!E39="","",ROUND('2-分类汇总'!E39,2))
B19: 资产总计 | C19: =IF('1-汇总表'!E27="","",ROUND('1-汇总表'!E27,2)) | D19: =IF('1-汇总表'!F27="","",ROUND('1-汇总表'!F27,2)) | E19: =IF('1-汇总表'!G27="","",ROUND('1-汇总表'!G27,2)) | F19: =IF('1-汇总表'!H27="","",ROUND('1-汇总表'!H27,2)) | I19: 流动负债 | K19: =IF('2-分类汇总'!E40="","",ROUND('2-分类汇总'!E40,2))
B20: 流动负债 | C20: =IF('1-汇总表'!E28="","",ROUND('1-汇总表'!E28,2)) | D20: =IF('1-汇总表'!F28="","",ROUND('1-汇总表'!F28,2)) | E20: =IF('1-汇总表'!G28="","",ROUND('1-汇总表'!G28,2)) | F20: =IF('1-汇总表'!H28="","",ROUND('1-汇总表'!H28,2)) | I20: 非流动负债 | K20: =IF('2-分类汇总'!E54="","",ROUND('2-分类汇总'!E54,2))
B21: 非流动负债 | C21: =IF('1-汇总表'!E29="","",ROUND('1-汇总表'!E29,2)) | D21: =IF('1-汇总表'!F29="","",ROUND('1-汇总表'!F29,2)) | E21: =IF('1-汇总表'!G29="","",ROUND('1-汇总表'!G29,2)) | F21: =IF('1-汇总表'!H29="","",ROUND('1-汇总表'!H29,2)) | I21: 负债合计 | K21: =IF('2-分类汇总'!E64="","",ROUND('2-分类汇总'!E64,2))
B22: 负债合计 | C22: =IF('1-汇总表'!E30="","",ROUND('1-汇总表'!E30,2)) | D22: =IF('1-汇总表'!F30="","",ROUND('1-汇总表'!F30,2)) | E22: =IF('1-汇总表'!G30="","",ROUND('1-汇总表'!G30,2)) | F22: =IF('1-汇总表'!H30="","",ROUND('1-汇总表'!H30,2)) | I22: 所有者权益(净资产) | K22: =IF('2-分类汇总'!E65="","",ROUND('2-分类汇总'!E65,2))
B23: 所有者权益(净资产) | C23: =IF('1-汇总表'!E31="","",ROUND('1-汇总表'!E31,2)) | D23: =IF('1-汇总表'!F31="","",ROUND('1-汇总表'!F31,2)) | E23: =IF('1-汇总表'!G31="","",ROUND('1-汇总表'!G31,2)) | F23: =IF('1-汇总表'!H31="","",ROUND('1-汇总表'!H31,2))
I24: 注：非流动资产只列示了常用科目，可根据实际情况增加。

Sheet 公式数据表
A4: 账龄设置
B5: 账龄 | C5: D值
C6: 下限 | D6: 上限 | G6: D=（评估基准日-发生日期）/365
B7: 1年以内 | C7: 0 | D7: 1
B8: 1～2年 | C8: 1 | D8: 2
B9: 2～3年 | C9: 2 | D9: 3
B10: 3年以上 | C10: 3

Sheet 设置
D2: 左页脚信息
C3: =设定信息!$A$6&"填表人：" | D3: 张三
C4: 填表日期： | D4: 44617
D7: 右页脚信息
A8: 序号 | B8: 选定 | C8: 表页名称 | D8: 评估专业人员姓名
A9: 1 | B9: √ | C9: 1-汇总表
A10: 2 | B10: √ | C10: 2-分类汇总
A11: 3 | B11: √ | C11: 3-流动资产汇总
A12: 3-1 | B12: √ | C12: 3-1货币资金汇总表
A13: 3-1-1 | B13: √ | C13: 3-1-1现金
A14: 3-1-2 | B14: √ | C14: 3-1-2银行存款
A15: 3-1-3 | B15: √ | C15: 3-1-3其他货币资金
A16: 3-2 | B16: √ | C16: 3-2交易性金融资产汇总
A17: 3-2-1 | B17: √ | C17: 3-2-1-股票 | D17: 张三 李四
A18: 3-2-2 | B18: √ | C18: 3-2-2-债券 | D18: 张三 李四
A19: 3-2-3 | B19: √ | C19: 3-2-3-基金 | D19: 张三 李四
A20: 3-3 | B20: √ | C20: 3-3衍生金融资产 | D20: 张三 李四
A21: 3-4 | B21: √ | C21: 3-4应收票据 | D21: 张三 李四
A22: 3-5 | B22: √ | C22: 3-5应收账款 | D22: 张三 李四
A23: 3-6 | B23: √ | C23: 3-6应收款项融资 | D23: 张三 李四
A24: 3-7 | B24: √ | C24: 3-7预付款项 | D24: 张三 李四
A25: 3-8 | B25: √ | C25: 3-8其他应收款汇总 | D25: 张三 李四
A26: 3-8-1 | B26: √ | C26: 3-8-1应收利息 | D26: 张三 李四
A27: 3-8-2 | B27: √ | C27: 3-8-2应收股利 | D27: 张三 李四
A28: 3-8-3 | B28: √ | C28: 3-8-3其他应收款 | D28: 张三 李四
... A35: 3-9-6 | B35: √ | C35: 3-9-6在产品（自制半成品） | D35: 张三 李四
A36: 3-9-7 | B36: √ | C36: 3-9-7发出商品
A37: 3-9-8 | B37: √ | C37: 3-9-8在用周转材料
A38: 3-9-9 | B38: √ | C38: 3-9-9合同履约成本
A39: 3-10 | B39: √ | C39: 3-10合同资产
A40: 3-11 | B40: √ | C40: 3-11持有待售资产
A41: 3-12 | B41: √ | C41: 3-12一年到期非流动资产
A42: 3-13 | B42: √ | C42: 3-13其他流动资产
A43: 4 | B43: √ | C43: 4-非流动资产汇总
A44: 4-1 | B44: √ | C44: 4-1债权投资
A45: 4-2 | B45: √ | C45: 4-2其他债权投资
A46: 4-3 | B46: √ | C46: 4-3长期应收
A47: 4-4 | B47: √ | C47: 4-4股权投资
... A108: 6-9 | B108: √ | C108: 6-9其他非流动负债

Sheet 0-其他方法结论
D2: 请输入
C4: 合并报表归属于母公司的净资产 | E4: 万元
C5: 收益法评估结果 | E5: 万元
C6: 市场法评估结果 | E6: 万元
C7: 结论方法 | D7: 收益法
C8: 未作为结论方法 | D8: 资产基础法
C9: 评估结果及增减值率
C10: 项目 | D10: 账面价值(万元） | E10: 评估结果(万元） | F10: 增值额(万元） | G10: 增值率% | H10: 评估值结果大写 | I10: 评估方法名称 | J10: 增值/减值
D11: A | E11: B | F11: C=B-A | G11: D=C/A×100
A12: 1 | B12: 资产结果 | C12: 资产基础法 | D12: ='1-汇总表'!E31 | E12: ='1-汇总表'!F31 | F12: =E12-D12 | G12: =IF(D12=0,"",ROUND(F12/D12*100,2)) | H12: =IF(E12<0,"负"&NUMBERSTRING(ABS(E12)*10000,2),NUMBERSTRING(ABS(E12)*10000,2)) | I12: =C12 | J12: =IF(F12>0.001,"评估增值",IF(F12<-0.001,"评估减值","无评估增减值"))
A13: 2 | B13: 收益结果 | C13: 收益法 | D13: =$D$12 | E13: =D5 | F13: =E13-D13 | G13: =IF(D13=0,"",ROUND(F13/D13*100,2)) | H13: =IF(E13<0,"负"&NUMBERSTRING(ABS(E13)*10000,2),NUMBERSTRING(ABS(E13)*10000,2)) | I13: =C13 | J13: =IF(F13>0.001,"评估增值",IF(F13<-0.001,"评估减值","无评估增减值"))
A14: 3 | B14: 市场结果 | C14: 市场法 | D14: =$D$12 | E14: =D6 | F14: =E14-D14 | G14: =IF(D14=0,"",ROUND(F14/D14*100,2)) | H14: =IF(E14<0,"负"&NUMBERSTRING(ABS(E14)*10000,2),NUMBERSTRING(ABS(E14)*10000,2)) | I14: =C14 | J14: =IF(F14>0.001,"评估增值",IF(F14<-0.001,"评估减值","评估无增减值"))
A15: 4 | B15: 成本结果 | C15: 成本法 | D15: =$D$12 | E15: =E12 | F15: =E15-D15 | G15: =IF(D15=0,"",ROUND(F15/D15*100,2)) | H15: =IF(E15<0,"负"&NUMBERSTRING(ABS(E15)*10000,2),NUMBERSTRING(ABS(E15)*10000,2)) | I15: =C15 | J15: =IF(F15>0.001,"评估增值",IF(F15<-0.001,"评估减值","评估无增减值"))
A16: 5 | B16: 不适用 | C16: 不适用 | I16: =C16
A17: 6 | B17: 最终结果 | C17: 最终结果 | D17: =INDEX(D12:D16,MATCH(D7,C12:C16,0)) | E17: =INDEX(E12:E16,MATCH(D7,C12:C16,0)) | F17: =E17-D17 | G17: =IF(D17=0,"",ROUND(F17/D17*100,2)) | H17: =IF(E17<0,"负"&NUMBERSTRING(ABS(E17)*10000,2),NUMBERSTRING(ABS(E17)*10000,2)) | I17: =D7 | J17: =IF(F17>0.001,"评估增值",IF(F17<-0.001,"评估减值","评估无增减值"))
A18: 7 | B18: 未用结果 | C18: 未采用结果 | D18: =INDEX(D12:D16,MATCH(D8,C12:C16,0)) | E18: =INDEX(E12:E16,MATCH(D8,C12:C16,0)) | F18: =E18-D18 | G18: =IF(D18=0,"",ROUND(F18/D18*100,2)) | H18: =IF(E18<0,"负"&NUMBERSTRING(ABS(E18)*10000,2),NUMBERSTRING(ABS(E18)*10000,2)) | I18: =D8 | J18: =IF(F18>0.001,"评估增值",IF(F18<-0.001,"评估减值","评估无增减值"))
A19: 8 | B19: 合表增减 | C19: 与合并报表比较 | D19: =D4 | E19: =E17 | F19: =E19-D19 | G19: =IF(D19=0,"",ROUND(F19/D19*100,2)) | H19: =IF(E19<0,"负"&NUMBERSTRING(ABS(E19)*10000,2),NUMBERSTRING(ABS(E19)*10000,2)) | I19: =D7 | J19: =IF(F19>0.001,"评估增值",IF(F19<-0.001,"评估减值","评估无增减值"))
C21: 不同方法的对比结果
C22: 方法比较 | D22: =C7 | E22: =C8 | F22: 差异绝对值（万元） | G22: 差异率%
A23: 9 | B23: 差异对比 | C23: 不同方法的对比 | D23: =INDEX(E12:E16,MATCH(D7,C12:C16,0)) | E23: =INDEX(E12:E16,MATCH(D8,C12:C16,0)) | F23: =ABS(D23-E23) | G23: =IF(E13=0,"",ROUND(F23/MAX(D23,E23)*100,2))

Sheet 设定信息
A1: TYPG-XT-ZPX-3.4.56
A5: 基本信息：
A6: 被评估单位 | B6: 浙江ABC有限责任公司
A7: 评估基准日 | B7: 44926
A8: 除“1-汇总表”金额单位 | B8: 人民币元
A9: “1-汇总表”金额单位 | B9: 人民币万元
A11: 审计机构名称 | B11: XX会计师事务所
A12: 审计报告文号 | B12: 审〔2023〕XXX号
A13: 审计报告意见类型 | B13: 标准的无保留意见
A14: 审计报告名称 | B14: XX公司审计报告
A15: 审计报告出具日期 | B15: 44949
A25: 填表注意事项：
A26: 1.请注意粘帖明细表时，用选择性粘帖，否则单元格格式将被修改。
A27: 2.若增减行数，打印前请注意使表格满页。
A28: 3.打印前请增加页脚信息，页脚评估人员应包含两位签字评估师+其他参与操作人员。
A29: 4.用不到的表页，应隐藏，不能删除。

Sheet 1-汇总表
B1: 资产评估结果汇总表
B2: ='2-分类汇总'!B2
H3: 表1
B4: ='2-分类汇总'!B4 | H4: =RIGHT(设定信息!A9,4)&"："&设定信息!B9
B5: 项 目 | E5: 账面价值 | F5: 评估价值 | G5: 增值额 | H5: 增值率％
E6: A | F6: B | G6: C=B-A | H6: D=C/A×100
B7: 1 | C7: 流资汇总 | D7: 流动资产 | E7: =ROUND('3-流动资产汇总'!E26/10000,2) | F7: =ROUND('3-流动资产汇总'!F26/10000,2) | G7: =IF((F7-E7)=0,"",(F7-E7)) | H7: =IF(OR(E7=0,E7="",G7=""),"",IF(E7<0,-G7/E7*100,G7/E7*100))
B8: 2 | C8: 非资汇总 | D8: 非流动资产 | E8: =ROUND('4-非流动资产汇总'!E27/10000,2) | F8: =ROUND('4-非流动资产汇总'!F27/10000,2) | G8: =IF((F8-E8)=0,"",(F8-E8)) | H8: =IF(OR(E8=0,E8="",G8=""),"",IF(E8<0,-G8/E8*100,G8/E8*100))
B9: 3 | C9: 债权投资 | D9: 其中：债权投资 | E9: =ROUND('4-非流动资产汇总'!E6/10000,2) | F9: =ROUND('4-非流动资产汇总'!F6/10000,2) | G9: =IF((F9-E9)=0,"",(F9-E9)) | H9: =IF(OR(E9=0,E9="",G9=""),"",IF(E9<0,-G9/E9*100,G9/E9*100))
B10: 4 | C10: 其他债权 | D10: 其他债权投资 | E10: =ROUND('4-非流动资产汇总'!E7/10000,2) | F10: =ROUND('4-非流动资产汇总'!F7/10000,2) | G10: =IF((F10-E10)=0,"",(F10-E10)) | H10: =IF(OR(E10=0,E10="",G10=""),"",IF(E10<0,-G10/E10*100,G10/E10*100))
B11: 5 | C11: 长期应收 | D11: 长期应收款 | E11: =ROUND('4-非流动资产汇总'!E8/10000,2) | F11: =ROUND('4-非流动资产汇总'!F8/10000,2) | G11: =IF((F11-E11)=0,"",(F11-E11)) | H11: =IF(OR(E11=0,E11="",G11=""),"",IF(E11<0,-G11/E11*100,G11/E11*100))
B12: 6 | C12: 长期股权 | D12: 长期股权投资 | E12: =ROUND('4-非流动资产汇总'!E9/10000,2) | F12: =ROUND('4-非流动资产汇总'!F9/10000,2) | G12: =IF((F12-E12)=0,"",(F12-E12)) | H12: =IF(OR(E12=0,E12="",G12=""),"",IF(E12<0,-G12/E12*100,G12/E12*100))
B13: 7 | C13: 其他权投 | D13: 其他权益工具投资 | E13: =ROUND('4-非流动资产汇总'!E10/10000,2) | F13: =ROUND('4-非流动资产汇总'!F10/10000,2) | G13: =IF((F13-E13)=0,"",(F13-E13)) | H13: =IF(OR(E13=0,E13="",G13=""),"",IF(E13<0,-G13/E13*100,G13/E13*100))
B14: 8 | C14: 其他非金 | D14: 其他非流动金融资产 | E14: =ROUND('4-非流动资产汇总'!E11/10000,2) | F14: =ROUND('4-非流动资产汇总'!F11/10000,2) | G14: =IF((F14-E14)=0,"",(F14-E14)) | H14: =IF(OR(E14=0,E14="",G14=""),"",IF(E14<0,-G14/E14*100,G14/E14*100))
B15: 9 | C15: 投房汇总 | D15: 投资性房地产 | E15: =ROUND('4-非流动资产汇总'!E12/10000,2) | F15: =ROUND('4-非流动资产汇总'!F12/10000,2) | G15: =IF((F15-E15)=0,"",(F15-E15)) | H15: =IF(OR(E15=0,E15="",G15=""),"",IF(E15<0,-G15/E15*100,G15/E15*100))
B16: 10 | C16: 固资汇总 | D16: 固定资产 | E16: =ROUND('4-非流动资产汇总'!E13/10000,2) | F16: =ROUND('4-非流动资产汇总'!F13/10000,2) | G16: =IF((F16-E16)=0,"",(F16-E16)) | H16: =IF(OR(E16=0,E16="",G16=""),"",IF(E16<0,-G16/E16*100,G16/E16*100))
B17: 11 | C17: 在建汇总 | D17: 在建工程 | E17: =ROUND('4-非流动资产汇总'!E14/10000,2) | F17: =ROUND('4-非流动资产汇总'!F14/10000,2) | G17: =IF((F17-E17)=0,"",(F17-E17)) | H17: =IF(OR(E17=0,E17="",G17=""),"",IF(E17<0,-G17/E17*100,G17/E17*100))
B18: 12 | C18: 生物资产 | D18: 生产性生物资产 | E18: =ROUND('4-非流动资产汇总'!E15/10000,2) | F18: =ROUND('4-非流动资产汇总'!F15/10000,2) | G18: =IF((F18-E18)=0,"",(F18-E18)) | H18: =IF(OR(E18=0,E18="",G18=""),"",IF(E18<0,-G18/E18*100,G18/E18*100))
B19: 13 | C19: 油气资产 | D19: 油气资产 | E19: =ROUND('4-非流动资产汇总'!E16/10000,2) | F19: =ROUND('4-非流动资产汇总'!F16/10000,2) | G19: =IF((F19-E19)=0,"",(F19-E19)) | H19: =IF(OR(E19=0,E19="",G19=""),"",IF(E19<0,-G19/E19*100,G19/E19*100))
B20: 14 | C20: 使用资产 | D20: 使用权资产 | E20: =ROUND('4-非流动资产汇总'!E17/10000,2) | F20: =ROUND('4-非流动资产汇总'!F17/10000,2) | G20: =IF((F20-E20)=0,"",(F20-E20)) | H20: =IF(OR(E20=0,E20="",G20=""),"",IF(E20<0,-G20/E20*100,G20/E20*100))
... B26: 20 | C26: 其他非资 | D26: 其他非流动资产 | E26: =ROUND('4-非流动资产汇总'!E23/10000,2) | F26: =ROUND('4-非流动资产汇总'!F23/10000,2) | G26: =IF((F26-E26)=0,"",(F26-E26)) | H26: =IF(OR(E26=0,E26="",G26=""),"",IF(E26<0,-G26/E26*100,G26/E26*100))
B27: 21 | C27: 资产总计 | D27: 资产总计 | E27: =SUM(E7:E8) | F27: =SUM(F7:F8) | G27: =IF((F27-E27)=0,"",(F27-E27)) | H27: =IF(OR(E27=0,E27="",G27=""),"",IF(E27<0,-G27/E27*100,G27/E27*100))
B28: 22 | C28: 流债汇总 | D28: 流动负债 | E28: =ROUND('5-流动负债汇总'!E27/10000,2) | F28: =ROUND('5-流动负债汇总'!F27/10000,2) | G28: =IF((F28-E28)=0,"",(F28-E28)) | H28: =IF(OR(E28=0,E28="",G28=""),"",IF(E28<0,-G28/E28*100,G28/E28*100))
B29: 23 | C29: 非债汇总 | D29: 非流动负债 | E29: =ROUND('6-非流动负债汇总'!E27/10000,2) | F29: =ROUND('6-非流动负债汇总'!F27/10000,2) | G29: =IF((F29-E29)=0,"",(F29-E29)) | H29: =IF(OR(E29=0,E29="",G29=""),"",IF(E29<0,-G29/E29*100,G29/E29*100))
B30: 24 | C30: 负债总计 | D30: 负债合计 | E30: =SUM(E28:E29) | F30: =SUM(F28:F29) | G30: =IF((F30-E30)=0,"",(F30-E30)) | H30: =IF(OR(E30=0,E30="",G30=""),"",IF(E30<0,-G30/E30*100,G30/E30*100))
A31: 合计1 | B31: 25 | C31: 股东权益 | D31: 净资产（所有者权益） | E31: =E27-E30 | F31: =F27-F30 | G31: =IF((F31-E31)=0,"",(F31-E31)) | H31: =IF(OR(E31=0,E31="",G31=""),"",IF(E31<0,-G31/E31*100,G31/E31*100))
E33: =IF(ABS(E27-E30-E31)<0.001,"","不平") | F33: =IF(ABS(F27-F30-F31)<0.001,"","不平") | H33: 评估机构：天源资产评估有限公司
D34: 校验 | E34: =IF(AND('2-分类汇总'!E39/10000-E27>-0.01,'2-分类汇总'!E39/10000-E27<0.01),"无误","合计有误") | F34: =IF(AND('2-分类汇总'!F39/10000-F27>-0.01,'2-分类汇总'!F39/10000-F27<0.01),"无误","合计有误")
E35: =IF(AND('2-分类汇总'!E65/10000-E31>-0.01,'2-分类汇总'!E65/10000-E31<0.01),"无误","合计有误") | F35: =IF(AND('2-分类汇总'!F65/10000-F31>-0.01,'2-分类汇总'!F65/10000-F31<0.01),"无误","合计有误")
E36: =IF(AND((E8-SUM(E9:E26))>-0.01,(E8-SUM(E9:E26))<0.01),"无误","合计有误") | F36: =IF(AND((F8-SUM(F9:F26))>-0.01,(F8-SUM(F9:F26))<0.01),"无误","合计有误")

Sheet 2-分类汇总
B1: 资产评估结果分类汇总表
B2: =设定信息!A7&"："&TEXT(评估基准日,"yyyy年m月d日")
H3: 表2
B4: =设定信息!A6&"："&设定信息!B6 | H4: =RIGHT(设定信息!A8,4)&"："&设定信息!B8
B5: 序号 | C5: 项目编号 | D5: 科目名称 | E5: 账面价值 | F5: 评估价值 | G5: 增值额 | H5: 增值率% | I5: 报表金额 | J5: 校验 | K5: 科目链接
B6: 1 | C6: 流资汇总 | D6: 一、流动资产合计 | E6: =SUM(E7:E19) | F6: =SUM(F7:F19) | G6: =F6-E6 | H6: =IF(E6=0,"",IF(E6<0,-G6/E6*100,G6/E6*100)) | I6: =SUM(I7:I19) | J6: =E6-I6
B7: 2 | C7: 货币汇总 | D7: 货币资金 | E7: ='3-流动资产汇总'!E6 | F7: ='3-流动资产汇总'!F6 | G7: =F7-E7 | H7: =IF(E7=0,"",IF(E7<0,-G7/E7*100,G7/E7*100)) | J7: =E7-I7 | K7: =HYPERLINK("#\"3-1货币资金汇总表\"!A1","货币资金")
B8: 3 | C8: 交融汇总 | D8: 交易性金融资产 | E8: ='3-流动资产汇总'!E7 | F8: ='3-流动资产汇总'!F7 | G8: =F8-E8 | H8: =IF(E8=0,"",IF(E8<0,-G8/E8*100,G8/E8*100)) | J8: =E8-I8 | K8: =HYPERLINK("#\"3-2交易性金融资产汇总\"!A1","交易性金融资产")
B9: 4 | C9: 衍金资产 | D9: 衍生金融资产 | E9: ='3-流动资产汇总'!E8 | F9: ='3-流动资产汇总'!F8 | G9: =F9-E9 | H9: =IF(E9=0,"",IF(E9<0,-G9/E9*100,G9/E9*100)) | J9: =E9-I9 | K9: =HYPERLINK("#\"3-3衍生金融资产\"!A1","衍生金融资产")
B10: 5 | C10: 应收票据 | D10: 应收票据 | E10: ='3-流动资产汇总'!E9 | F10: ='3-流动资产汇总'!F9 | G10: =F10-E10 | H10: =IF(E10=0,"",IF(E10<0,-G10/E10*100,G10/E10*100)) | J10: =E10-I10 | K10: =HYPERLINK("#\"3-4应收票据\"!A1","应收票据")
B11: 6 | C11: 应收账款 | D11: 应收账款 | E11: ='3-流动资产汇总'!E10 | F11: ='3-流动资产汇总'!F10 | G11: =F11-E11 | H11: =IF(E11=0,"",IF(E11<0,-G11/E11*100,G11/E11*100)) | J11: =E11-I11 | K11: =HYPERLINK("#\"3-5应收账款\"!A1","应收账款")
B12: 7 | C12: 应收融资 | D12: 应收款项融资 | E12: ='3-流动资产汇总'!E11 | F12: ='3-流动资产汇总'!F11 | G12: =F12-E12 | H12: =IF(E12=0,"",IF(E12<0,-G12/E12*100,G12/E12*100)) | J12: =E12-I12 | K12: =HYPERLINK("#\"3-6应收款项融资\"!A1","应收款项融资")
B13: 8 | C13: 预付账款 | D13: 预付款项 | E13: ='3-流动资产汇总'!E12 | F13: ='3-流动资产汇总'!F12 | G13: =F13-E13 | H13: =IF(E13=0,"",IF(E13<0,-G13/E13*100,G13/E13*100)) | J13: =E13-I13 | K13: =HYPERLINK("#\"3-7预付款项\"!A1","预付款项")
B14: 9 | C14: 其收汇总 | D14: 其他应收款 | E14: ='3-流动资产汇总'!E13 | F14: ='3-流动资产汇总'!F13 | G14: =F14-E14 | H14: =IF(E14=0,"",IF(E14<0,-G14/E14*100,G14/E14*100)) | J14: =E14-I14 | K14: =HYPERLINK("#\"3-8其他应收款汇总\"!A1","其他应收款")
B15: 10 | C15: 存货汇总 | D15: 存货 | E15: ='3-流动资产汇总'!E14 | F15: ='3-流动资产汇总'!F14 | G15: =F15-E15 | H15: =IF(E15=0,"",IF(E15<0,-G15/E15*100,G15/E15*100)) | J15: =E15-I15 | K15: =HYPERLINK("#\"3-9存货汇总\"!A1","存货")
B16: 11 | C16: 合同资产 | D16: 合同资产 | E16: ='3-流动资产汇总'!E15 | F16: ='3-流动资产汇总'!F15 | G16: =F16-E16 | H16: =IF(E16=0,"",IF(E16<0,-G16/E16*100,G16/E16*100)) | J16: =E16-I16 | K16: =HYPERLINK("#\"3-10合同资产\"!A1","合同资产")
B17: 12 | C17: 持有代资 | D17: 持有待售资产 | E17: ='3-流动资产汇总'!E16 | F17: ='3-流动资产汇总'!F16 | G17: =F17-E17 | H17: =IF(E17=0,"",IF(E17<0,-G17/E17*100,G17/E17*100)) | J17: =E17-I17 | K17: =HYPERLINK("#\"3-11持有待售资产\"!A1","持有待售资产")
B18: 13 | C18: 到期非流 | D18: 一年内到期的非流动资产 | E18: ='3-流动资产汇总'!E17 | F18: ='3-流动资产汇总'!F17 | G18: =F18-E18 | H18: =IF(E18=0,"",IF(E18<0,-G18/E18*100,G18/E18*100)) | J18: =E18-I18 | K18: =HYPERLINK("#\"3-12一年到期非流动资产\"!A1","一年内到期的非流动资产")
B19: 14 | C19: 其他流资 | D19: 其他流动资产 | E19: ='3-流动资产汇总'!E18 | F19: ='3-流动资产汇总'!F18 | G19: =F19-E19 | H19: =IF(E19=0,"",IF(E19<0,-G19/E19*100,G19/E19*100)) | J19: =E19-I19 | K19: =HYPERLINK("#\"3-13其他流动资产\"!A1","其他流动资产")
B20: 15 | C20: 非资汇总 | D20: 二、非流动资产合计 | E20: =SUM(E21:E38) | F20: =SUM(F21:F38) | G20: =F20-E20 | H20: =IF(E20=0,"",IF(E20<0,-G20/E20*100,G20/E20*100)) | I20: =SUM(I21:I38) | J20: =E20-I20
B21: 16 | C21: 债权投资 | D21: 债权投资 | E21: ='4-非流动资产汇总'!E6 | F21: ='4-非流动资产汇总'!F6 | G21: =F21-E21 | H21: =IF(E21=0,"",IF(E21<0,-G21/E21*100,G21/E21*100)) | J21: =E21-I21 | K21: =HYPERLINK("#\"4-1债权投资\"!A1","债权投资")
B22: 17 | C22: 其他债权 | D22: 其他债权投资 | E22: ='4-非流动资产汇总'!E7 | F22: ='4-非流动资产汇总'!F7 | G22: =F22-E22 | H22: =IF(E22=0,"",IF(E22<0,-G22/E22*100,G22/E22*100)) | J22: =E22-I22 | K22: =HYPERLINK("#\"4-2其他债权投资\"!A1","其他债权投资")
B23: 18 | C23: 长期应收 | D23: 长期应收款 | E23: ='4-非流动资产汇总'!E8 | F23: ='4-非流动资产汇总'!F8 | G23: =F23-E23 | H23: =IF(E23=0,"",IF(E23<0,-G23/E23*100,G23/E23*100)) | J23: =E23-I23 | K23: =HYPERLINK("#\"4-3长期应收\"!A1","长期应收款")
B24: 19 | C24: 长期股权 | D24: 长期股权投资 | E24: ='4-非流动资产汇总'!E9 | F24: ='4-非流动资产汇总'!F9 | G24: =F24-E24 | H24: =IF(E24=0,"",IF(E24<0,-G24/E24*100,G24/E24*100)) | J24: =E24-I24 | K24: =HYPERLINK("#\"4-4股权投资\"!A1","长期股权投资")
B25: 20 | C25: 其他权投 | D25: 其他权益工具投资 | E25: ='4-非流动资产汇总'!E10 | F25: ='4-非流动资产汇总'!F10 | G25: =F25-E25 | H25: =IF(E25=0,"",IF(E25<0,-G25/E25*100,G25/E25*100)) | J25: =E25-I25 | K25: =HYPERLINK("#\"4-5其他权益工具投资\"!A1","其他权益工具投资")
B26: 21 | C26: 其他非金 | D26: 其他非流动金融资产 | E26: ='4-非流动资产汇总'!E11 | F26: ='4-非流动资产汇总'!F11 | G26: =F26-E26 | H26: =IF(E26=0,"",IF(E26<0,-G26/E26*100,G26/E26*100)) | J26: =E26-I26 | K26: =HYPERLINK("#\"4-6其他非流动金融资产汇总\"!A1","其他非流动金融资产")
B27: 22 | C27: 投房汇总 | D27: 投资性房地产 | E27: ='4-非流动资产汇总'!E12 | F27: ='4-非流动资产汇总'!F12 | G27: =F27-E27 | H27: =IF(E27=0,"",IF(E27<0,-G27/E27*100,G27/E27*100)) | J27: =E27-I27 | K27: =HYPERLINK("#\"4-7投资性房地产汇总\"!A1","投资性房地产")
B28: 23 | C28: 固资汇总 | D28: 固定资产 | E28: ='4-非流动资产汇总'!E13 | F28: ='4-非流动资产汇总'!F13 | G28: =F28-E28 | H28: =IF(E28=0,"",IF(E28<0,-G28/E28*100,G28/E28*100)) | J28: =E28-I28 | K28: =HYPERLINK("#\"4-8固定资产汇总\"!A1","固定资产")
B29: 24 | C29: 在建汇总 | D29: 在建工程 | E29: ='4-非流动资产汇总'!E14 | F29: ='4-非流动资产汇总'!F14 | G29: =F29-E29 | H29: =IF(E29=0,"",IF(E29<0,-G29/E29*100,G29/E29*100)) | J29: =E29-I29 | K29: =HYPERLINK("#\"4-9在建工程汇总\"!A1","在建工程")
B30: 25 | C30: 生物资产 | D30: 生产性生物资产 | E30: ='4-非流动资产汇总'!E15 | F30: ='4-非流动资产汇总'!F15 | G30: =F30-E30 | H30: =IF(E30=0,"",IF(E30<0,-G30/E30*100,G30/E30*100)) | J30: =E30-I30 | K30: =HYPERLINK("#\"4-10生产性生物资产\"!A1","生产性生物资产")
B31: 26 | C31: 油气资产 | D31: 油气资产 | E31: ='4-非流动资产汇总'!E16 | F31: ='4-非流动资产汇总'!F16 | G31: =F31-E31 | H31: =IF(E31=0,"",IF(E31<0,-G31/E31*100,G31/E31*100)) | J31: =E31-I31 | K31: =HYPERLINK("#\"4-11油气资产\"!A1","油气资产")
B32: 27 | C32: 使用资产 | D32: 使用权资产 | E32: ='4-非流动资产汇总'!E17 | F32: ='4-非流动资产汇总'!F17 | G32: =F32-E32 | H32: =IF(E32=0,"",IF(E32<0,-G32/E32*100,G32/E32*100)) | J32: =E32-I32 | K32: =HYPERLINK("#\"4-12使用权资产\"!A1","使用权资产")
B33: 28 | C33: 无形汇总 | D33: 无形资产 | E33: ='4-非流动资产汇总'!E18 | F33: ='4-非流动资产汇总'!F18 | G33: =F33-E33 | H33: =IF(E33=0,"",IF(E33<0,-G33/E33*100,G33/E33*100)) | J33: =E33-I33 | K33: =HYPERLINK("#\"4-13无形资产汇总\"!A1","无形资产")
B34: 29 | C34: 开发支出 | D34: 开发支出 | E34: ='4-非流动资产汇总'!E19 | F34: ='4-非流动资产汇总'!F19 | G34: =F34-E34 | H34: =IF(E34=0,"",IF(E34<0,-G34/E34*100,G34/E34*100)) | J34: =E34-I34 | K34: =HYPERLINK("#\"4-14开发支出\"!A1","开发支出")
B35: 30 | C35: 商誉资产 | D35: 商誉 | E35: ='4-非流动资产汇总'!E20 | F35: ='4-非流动资产汇总'!F20 | G35: =F35-E35 | H35: =IF(E35=0,"",IF(E35<0,-G35/E35*100,G35/E35*100)) | J35: =E35-I35 | K35: =HYPERLINK("#\"4-15商誉\"!A1","商誉")
B36: 31 | C36: 长期待摊 | D36: 长期待摊费用 | E36: ='4-非流动资产汇总'!E21 | F36: ='4-非流动资产汇总'!F21 | G36: =F36-E36 | H36: =IF(E36=0,"",IF(E36<0,-G36/E36*100,G36/E36*100)) | J36: =E36-I36 | K36: =HYPERLINK("#\"4-16长期待摊费用\"!A1","长期待摊费用")
B37: 32 | C37: 递延资产 | D37: 递延所得税资产 | E37: ='4-非流动资产汇总'!E22 | F37: ='4-非流动资产汇总'!F22 | G37: =F37-E37 | H37: =IF(E37=0,"",IF(E37<0,-G37/E37*100,G37/E37*100)) | J37: =E37-I37 | K37: =HYPERLINK("#\"4-17递延所得税资产\"!A1","递延所得税资产")
B38: 33 | C38: 其他非资 | D38: 其他非流动资产 | E38: ='4-非流动资产汇总'!E23 | F38: ='4-非流动资产汇总'!F23 | G38: =F38-E38 | H38: =IF(E38=0,"",IF(E38<0,-G38/E38*100,G38/E38*100)) | J38: =E38-I38 | K38: =HYPERLINK("#\"4-18其他非流动资产\"!A1","其他非流动资产")
B39: 34 | C39: 资产总计 | D39: 三、资产总计 | E39: =E6+E20 | F39: =F6+F20 | G39: =F39-E39 | H39: =IF(E39=0,"",IF(E39<0,-G39/E39*100,G39/E39*100)) | I39: =I6+I20 | J39: =E39-I39
B40: 35 | C40: 流债汇总 | D40: 四、流动负债合计 | E40: =SUM(E41:E53) | F40: =SUM(F41:F53) | G40: =F40-E40 | H40: =IF(E40=0,"",IF(E40<0,-G40/E40*100,G40/E40*100)) | I40: =SUM(I41:I53) | J40: =E40-I40
...

Sheet 3-流动资产汇总
B1: 流动资产评估汇总表
B2: ='2-分类汇总'!B2
H3: 表3
B4: ='2-分类汇总'!B4 | H4: ='2-分类汇总'!H4
B5: 编号 | C5: 项目编号 | D5: 科目名称 | E5: 账面价值 | F5: 评估价值 | G5: 增值额 | H5: 增值率%
B6: 3-1 | C6: 货币汇总 | D6: 货币资金 | E6: ='3-1货币资金汇总表'!E23 | F6: ='3-1货币资金汇总表'!F23 | G6: =F6-E6 | H6: =IF(E6=0,"",G6/E6*100)
B7: 3-2 | C7: 交融汇总 | D7: 交易性金融资产 | E7: ='3-2交易性金融资产汇总'!E24 | F7: ='3-2交易性金融资产汇总'!F24 | G7: =F7-E7 | H7: =IF(E7=0,"",G7/E7*100)
B8: 3-3 | C8: 衍金资产 | D8: 衍生金融资产 | E8: ='3-3衍生金融资产'!F27 | F8: ='3-3衍生金融资产'!G27 | G8: =F8-E8 | H8: =IF(E8=0,"",G8/E8*100)
B9: 3-4 | C9: 应收票据 | D9: 应收票据 | E9: ='3-4应收票据'!G29 | F9: ='3-4应收票据'!H29 | G9: =F9-E9 | H9: =IF(E9=0,"",G9/E9*100)
B10: 3-5 | C10: 应收账款 | D10: 应收账款 | E10: ='3-5应收账款'!J29 | F10: ='3-5应收账款'!K29 | G10: =F10-E10 | H10: =IF(E10=0,"",G10/E10*100)
B11: 3-6 | C11: 应收融资 | D11: 应收款项融资 | E11: ='3-6应收款项融资'!J29 | F11: ='3-6应收款项融资'!K29 | G11: =F11-E11 | H11: =IF(E11=0,"",G11/E11*100)
B12: 3-7 | C12: 预付账款 | D12: 预付款项 | E12: ='3-7预付款项'!J28 | F12: ='3-7预付款项'!K28 | G12: =F12-E12 | H12: =IF(E12=0,"",G12/E12*100)
B13: 3-8 | C13: 其他应收 | D13: 其他应收款 | E13: ='3-8其他应收款汇总'!E25 | F13: ='3-8其他应收款汇总'!F25 | G13: =F13-E13 | H13: =IF(E13=0,"",G13/E13*100)
B14: 3-9 | C14: 存货汇总 | D14: 存货 | E14: ='3-9存货汇总'!E23 | F14: ='3-9存货汇总'!F23 | G14: =F14-E14 | H14: =IF(E14=0,"",G14/E14*100)
B15: 3-10 | C15: 合同资产 | D15: 合同资产 | E15: ='3-10合同资产'!F29 | F15: ='3-10合同资产'!G29 | G15: =F15-E15 | H15: =IF(E15=0,"",G15/E15*100)
B16: 3-11 | C16: 持有待资 | D16: 持有待售资产 | E16: ='3-11持有待售资产'!I30 | F16: ='3-11持有待售资产'!J30 | G16: =F16-E16 | H16: =IF(E16=0,"",G16/E16*100)
B17: 3-12 | C17: 到期非流 | D17: 一年内到期的非流动资产 | E17: ='3-12一年到期非流动资产'!F28 | F17: ='3-12一年到期非流动资产'!G28 | G17: =F17-E17 | H17: =IF(E17=0,"",G17/E17*100)
B18: 3-13 | C18: 其他流资 | D18: 其他流动资产 | E18: ='3-13其他流动资产'!G28 | F18: ='3-13其他流动资产'!H28 | G18: =F18-E18 | H18: =IF(E18=0,"",G18/E18*100)
A26: 合计1 | C26: 流资汇总 | D26: 流动资产合计 | E26: =SUM(E6:E25) | F26: =SUM(F6:F25) | G26: =F26-E26 | H26: =IF(E26=0,"",G26/E26*100)

Sheet 3-1货币资金汇总表
B1: 货币资金评估汇总表
B2: ='2-分类汇总'!B2
H3: 表3-1
B4: ='2-分类汇总'!B4 | I4: ='2-分类汇总'!H4
B5: 编号 | C5: 项目编号 | D5: 科目名称 | E5: 账面价值 | F5: 评估价值 | G5: 增值额 | H5: 增值率% | I5: 备注
B6: 3-1-1 | C6: 货币现金 | D6: 现金 | E6: ='3-1-1现金'!G27 | F6: ='3-1-1现金'!H27 | G6: =F6-E6 | H6: =IF(E6=0,"",G6/E6*100)
B7: 3-1-2 | C7: 货币银行 | D7: 银行存款 | E7: ='3-1-2银行存款'!H29 | F7: ='3-1-2银行存款'!I29 | G7: =F7-E7 | H7: =IF(E7=0,"",G7/E7*100)
B8: 3-1-3 | C8: 其他货币 | D8: 其他货币资金 | E8: ='3-1-3其他货币资金'!H31 | F8: ='3-1-3其他货币资金'!I31 | G8: =F8-E8 | H8: =IF(E8=0,"",G8/E8*100)
A23: 合计1 | C23: 货币汇总 | D23: 合 计 | E23: =SUM(E6:E22) | F23: =SUM(F6:F22) | G23: =F23-E23 | H23: =IF(E23=0,"",G23/E23*100)

Sheet 3-1-1现金
A1: 表头区域 | B1: 货币资金—现金评估明细表
A2: 表头区域 | B2: ='2-分类汇总'!B2
A3: 表头区域 | J3: 表3-1-1
A4: 表头区域 | B4: ='2-分类汇总'!B4 | K4: ='2-分类汇总'!H4
A5: 检索表头 | B5: 序号 | C5: 存放部门（单位) | D5: 币种 | E5: 外币账面金额 | F5: 评估基准日汇率 | G5: 账面价值 | H5: 评估价值 | I5: 增值额 | J5: 增值率% | K5: 备注
I6: =H6-G6 | J6: =IF(G6=0,"",I6/G6*100)
I7: =H7-G7 | J7: =IF(G7=0,"",I7/G7*100)
I8: =H8-G8 | J8: =IF(G8=0,"",I8/G8*100)
I9: =H9-G9 | J9: =IF(G9=0,"",I9/G9*100)
I10: =H10-G10 | J10: =IF(G10=0,"",I10/G10*100)
I11: =H11-G11 | J11: =IF(G11=0,"",I11/G11*100)
I12: =H12-G12 | J12: =IF(G12=0,"",I12/G12*100)
I13: =H13-G13 | J13: =IF(G13=0,"",I13/G13*100)
I14: =H14-G14 | J14: =IF(G14=0,"",I14/G14*100)
I15: =H15-G15 | J15: =IF(G15=0,"",I15/G15*100)
I16: =H16-G16 | J16: =IF(G16=0,"",I16/G16*100)
I17: =H17-G17 | J17: =IF(G17=0,"",I17/G17*100)
... I26: =H26-G26 | J26: =IF(G26=0,"",I26/G26*100)
A27: 合计1 | B27: 合 计 | G27: =ROUND(SUM(G6:G26),2) | H27: =ROUND(SUM(H6:H26),2) | I27: =H27-G27 | J27: =IF(G27=0,"",I27/G27*100)

Sheet 3-1-2银行存款
A1: 表头区域 | B1: 货币资金—银行存款评估明细表
A2: 表头区域 | B2: ='2-分类汇总'!B2
A3: 表头区域 | K3: 表3-1-2
A4: 表头区域 | B4: ='2-分类汇总'!B4 | L4: ='2-分类汇总'!H4
A5: 检索表头 | B5: 序号 | C5: 开户银行 | D5: 账号 | E5: 币种 | F5: 外币账面金额 | G5: 评估基准日汇率 | H5: 账面价值 | I5: 评估价值 | J5: 增值额 | K5: 增值率% | L5: 备注
J6: =I6-H6 | K6: =IF(H6=0,"",J6/H6*100)
J7: =I7-H7 | K7: =IF(H7=0,"",J7/H7*100)
J8: =I8-H8 | K8: =IF(H8=0,"",J8/H8*100)
J9: =I9-H9 | K9: =IF(H9=0,"",J9/H9*100)
J10: =I10-H10 | K10: =IF(H10=0,"",J10/H10*100)
J11: =I11-H11 | K11: =IF(H11=0,"",J11/H11*100)
J12: =I12-H12 | K12: =IF(H12=0,"",J12/H12*100)
J13: =I13-H13 | K13: =IF(H13=0,"",J13/H13*100)
J14: =I14-H14 | K14: =IF(H14=0,"",J14/H14*100)
J15: =I15-H15 | K15: =IF(H15=0,"",J15/H15*100)
J16: =I16-H16 | K16: =IF(H16=0,"",J16/H16*100)
J17: =I17-H17 | K17: =IF(H17=0,"",J17/H17*100)
... J28: =I28-H28 | K28: =IF(H28=0,"",J28/H28*100)
A29: 合计1 | B29: 合 计 | H29: =ROUND(SUM(H6:H28),2) | I29: =ROUND(SUM(I6:I28),2) | J29: =I29-H29 | K29: =IF(H29=0,"",J29/H29*100)

Sheet 3-1-3其他货币资金
A1: 表头区域 | B1: 货币资金—其他货币资金评估明细表
A2: 表头区域 | B2: ='2-分类汇总'!B2
A3: 表头区域 | L3: 表3-1-3
A4: 表头区域 | B4: ='2-分类汇总'!B4 | L4: ='2-分类汇总'!H4
A5: 检索表头 | B5: 序号 | C5: 名称及内容 | D5: 用途 | E5: 币种 | F5: 外币账面金额 | G5: 评估基准日汇率 | H5: 账面价值 | I5: 评估价值 | J5: 增值额 | K5: 增值率% | L5: 备注
J6: =I6-H6 | K6: =IF(H6=0,"",J6/H6*100)
J7: =I7-H7 | K7: =IF(H7=0,"",J7/H7*100)
J8: =I8-H8 | K8: =IF(H8=0,"",J8/H8*100)
J9: =I9-H9 | K9: =IF(H9=0,"",J9/H9*100)
J10: =I10-H10 | K10: =IF(H10=0,"",J10/H10*100)
J11: =I11-H11 | K11: =IF(H11=0,"",J11/H11*100)
J12: =I12-H12 | K12: =IF(H12=0,"",J12/H12*100)
J13: =I13-H13 | K13: =IF(H13=0,"",J13/H13*100)
J14: =I14-H14 | K14: =IF(H14=0,"",J14/H14*100)
J15: =I15-H15 | K15: =IF(H15=0,"",J15/H15*100)
J16: =I16-H16 | K16: =IF(H16=0,"",J16/H16*100)
J17: =I17-H17 | K17: =IF(H17=0,"",J17/H17*100)
... J30: =I30-H30 | K30: =IF(H30=0,"",J30/H30*100)
A31: 合计1 | B31: 合 计 | H31: =ROUND(SUM(H6:H30),2) | I31: =ROUND(SUM(I6:I30),2) | J31: =I31-H31 | K31: =IF(H31=0,"",J31/H31*100)

Sheet 3-2交易性金融资产汇总
B1: 交易性金融资产评估汇总表
B2: ='2-分类汇总'!B2
H3: 表3-2
B4: ='2-分类汇总'!B4 | H4: ='2-分类汇总'!H4
B5: 编号 | C5: 项目编号 | D5: 科目名称 | E5: 账面价值 | F5: 评估价值 | G5: 增值额 | H5: 增值率%
B6: 3-2-1 | C6: 交融股票 | D6: 交易性金融资产-股票投资 | E6: ='3-2-1-股票'!H29 | F6: ='3-2-1-股票'!J29 | G6: =F6-E6 | H6: =IF(E6=0,"",G6/E6*100)
B7: 3-2-2 | C7: 交融债券 | D7: 交易性金融资产-债券投资 | E7: ='3-2-2-债券'!I29 | F7: ='3-2-2-债券'!J29 | G7: =F7-E7 | H7: =IF(E7=0,"",G7/E7*100)
B8: 3-2-3 | C8: 交融基金 | D8: 交易性金融资产-基金投资 | E8: ='3-2-3-基金'!H31 | F8: ='3-2-3-基金'!J31 | G8: =F8-E8 | H8: =IF(E8=0,"",G8/E8*100)
A24: 合计1 | C24: 交融汇总 | D24: 合 计 | E24: =SUM(E6:E23) | F24: =SUM(F6:F23) | G24: =F24-E24 | H24: =IF(E24=0,"",G24/E24*100)

Sheet 3-2-1-股票
A1: 表头区域 | B1: 交易性金融资产—股票投资评估明细表
A2: 表头区域 | B2: ='2-分类汇总'!B2
A3: 表头区域 | L3: 表3-2-1
A4: 表头区域 | B4: ='2-分类汇总'!B4 | M4: ='2-分类汇总'!H4
A5: 检索表头 | B5: 序号 | C5: 被投资单位名称 | D5: 股票名称 | E5: 投资日期 | F5: 持股数量 | G5: 成 本 | H5: 账面价值 | I5: 基准日收盘价元/股 | J5: 评估价值 | K5: 增值额 | L5: 增值率% | M5: 备注
K6: =J6-H6 | L6: =IF(H6=0,"",K6/H6*100)
K7: =J7-H7 | L7: =IF(H7=0,"",K7/H7*100)
K8: =J8-H8 | L8: =IF(H8=0,"",K8/H8*100)
K9: =J9-H9 | L9: =IF(H9=0,"",K9/H9*100)
K10: =J10-H10 | L10: =IF(H10=0,"",K10/H10*100)
K11: =J11-H11 | L11: =IF(H11=0,"",K11/H11*100)
K12: =J12-H12 | L12: =IF(H12=0,"",K12/H12*100)
K13: =J13-H13 | L13: =IF(H13=0,"",K13/H13*100)
K14: =J14-H14 | L14: =IF(H14=0,"",K14/H14*100)
K15: =J15-H15 | L15: =IF(H15=0,"",K15/H15*100)
K16: =J16-H16 | L16: =IF(H16=0,"",K16/H16*100)
K17: =J17-H17 | L17: =IF(H17=0,"",K17/H17*100)
... K28: =J28-H28 | L28: =IF(H28=0,"",K28/H28*100)
A29: 合计1 | B29: 合 计 | G29: =ROUND(SUM(G6:G28),2) | H29: =ROUND(SUM(H6:H28),2) | J29: =ROUND(SUM(J6:J28),2) | K29: =J29-H29 | L29: =IF(H29=0,"",K29/H29*100)

Sheet 3-2-2-债券
A1: 表头区域 | B1: 交易性金融资产—债券投资评估明细表
A2: 表头区域 | B2: ='2-分类汇总'!B2
A3: 表头区域 | L3: 表3-2-2
A4: 表头区域 | B4: ='2-分类汇总'!B4 | M4: ='2-分类汇总'!H4
A5: 检索表头 | B5: 序号 | C5: 被投资单位名称 | D5: 债券名称 | E5: 发行日期 | F5: 投资日期 | G5: 票面利率% | H5: 成本 | I5: 账面价值 | J5: 评估价值 | K5: 增值额 | L5: 增值率% | M5: 备注
K6: =J6-I6 | L6: =IF(I6=0,"",K6/I6*100)
K7: =J7-I7 | L7: =IF(I7=0,"",K7/I7*100)
K8: =J8-I8 | L8: =IF(I8=0,"",K8/I8*100)
K9: =J9-I9 | L9: =IF(I9=0,"",K9/I9*100)
K10: =J10-I10 | L10: =IF(I10=0,"",K10/I10*100)
K11: =J11-I11 | L11: =IF(I11=0,"",K11/I11*100)
K12: =J12-I12 | L12: =IF(I12=0,"",K12/I12*100)
K13: =J13-I13 | L13: =IF(I13=0,"",K13/I13*100)
K14: =J14-I14 | L14: =IF(I14=0,"",K14/I14*100)
K15: =J15-I15 | L15: =IF(I15=0,"",K15/I15*100)
K16: =J16-I16 | L16: =IF(I16=0,"",K16/I16*100)
K17: =J17-I17 | L17: =IF(I17=0,"",K17/I17*100)
... K28: =J28-I28 | L28: =IF(I28=0,"",K28/I28*100)
A29: 合计1 | B29: 合 计 | I29: =ROUND(SUM(I6:I28),2) | J29: =ROUND(SUM(J6:J28),2) | K29: =J29-I29 | L29: =IF(I29=0,"",K29/I29*100)

Sheet 3-2-3-基金
A1: 表头区域 | B1: 交易性金融资产—基金投资评估明细表
A2: 表头区域 | B2: ='2-分类汇总'!B2
A3: 表头区域 | L3: 表3-2-3
A4: 表头区域 | B4: ='2-分类汇总'!B4 | M4: ='2-分类汇总'!H4
A5: 检索表头 | B5: 序号 | C5: 基金发行单位 | D5: 基金名称 | E5: 基金类型 | F5: 投资日期 | G5: 成本 | H5: 账面价值 | I5: 基准日净值/份 | J5: 评估价值 | K5: 增值额 | L5: 增值率% | M5: 备注
K6: =J6-H6 | L6: =IF(H6=0,"",K6/H6*100)
K7: =J7-H7 | L7: =IF(H7=0,"",K7/H7*100)
K8: =J8-H8 | L8: =IF(H8=0,"",K8/H8*100)
K9: =J9-H9 | L9: =IF(H9=0,"",K9/H9*100)
K10: =J10-H10 | L10: =IF(H10=0,"",K10/H10*100)
K11: =J11-H11 | L11: =IF(H11=0,"",K11/H11*100)
K12: =J12-H12 | L12: =IF(H12=0,"",K12/H12*100)
K13: =J13-H13 | L13: =IF(H13=0,"",K13/H13*100)
K14: =J14-H14 | L14: =IF(H14=0,"",K14/H14*100)
K15: =J15-H15 | L15: =IF(H15=0,"",K15/H15*100)
K16: =J16-H16 | L16: =IF(H16=0,"",K16/H16*100)
K17: =J17-H17 | L17: =IF(H17=0,"",K17/H17*100)
... K30: =J30-H30 | L30: =IF(H30=0,"",K30/H30*100)
A31: 合计1 | B31: 合 计 | H31: =ROUND(SUM(H6:H30),2) | J31: =ROUND(SUM(J6:J30),2) | K31: =J31-H31 | L31: =IF(H31=0,"",K31/H31*100)

Sheet 3-3衍生金融资产
A1: 表头区域 | B1: 衍生金融资产评估明细表
A2: 表头区域 | B2: ='2-分类汇总'!B2
A3: 表头区域 | J3: 表3-3
A4: 表头区域 | B4: ='2-分类汇总'!B4 | J4: ='2-分类汇总'!H4
A5: 检索表头 | B5: 序号 | C5: 被投资项目名称 | D5: 投资日期 | E5: 成本 | F5: 账面价值 | G5: 评估价值 | H5: 增值额 | I5: 增值率% | J5: 备注
H6: =G6-F6 | I6: =IF(F6=0,"",H6/F6*100)
H7: =G7-F7 | I7: =IF(F7=0,"",H7/F7*100)
H8: =G8-F8 | I8: =IF(F8=0,"",H8/F8*100)
H9: =G9-F9 | I9: =IF(F9=0,"",H9/F9*100)
H10: =G10-F10 | I10: =IF(F10=0,"",H10/F10*100)
H11: =G11-F11 | I11: =IF(F11=0,"",H11/F11*100)
H12: =G12-F12 | I12: =IF(F12=0,"",H12/F12*100)
H13: =G13-F13 | I13: =IF(F13=0,"",H13/F13*100)
H14: =G14-F14 | I14: =IF(F14=0,"",H14/F14*100)
H15: =G15-F15 | I15: =IF(F15=0,"",H15/F15*100)
H16: =G16-F16 | I16: =IF(F16=0,"",H16/F16*100)
H17: =G17-F17 | I17: =IF(F17=0,"",H17/F17*100)
... H26: =G26-F26 | I26: =IF(F26=0,"",H26/F26*100)
A27: 合计1 | B27: 合 计 | E27: =SUM(E6:E26) | F27: =SUM(F6:F26) | G27: =SUM(G6:G26) | H27: =G27-F27 | I27: =IF(F27=0,"",H27/F27*100)

Sheet 3-4应收票据
A1: 表头区域 | B1: 应收票据评估明细表
A2: 表头区域 | B2: ='2-分类汇总'!B2
A3: 表头区域 | K3: 表3-4
A4: 表头区域 | B4: ='2-分类汇总'!B4 | K4: ='2-分类汇总'!H4
A5: 检索表头 | B5: 序号 | C5: 户名（结算对象) | D5: 出票日期 | E5: 到期日期 | F5: 票面利率% | G5: 账面价值 | H5: 评估价值 | I5: 增值额 | J5: 增值率% | K5: 备注
I6: =H6-G6 | J6: =IF(G6=0,"",I6/G6*100)
I7: =H7-G7 | J7: =IF(G7=0,"",I7/G7*100)
I8: =H8-G8 | J8: =IF(G8=0,"",I8/G8*100)
I9: =H9-G9 | J9: =IF(G9=0,"",I9/G9*100)
I10: =H10-G10 | J10: =IF(G10=0,"",I10/G10*100)
I11: =H11-G11 | J11: =IF(G11=0,"",I11/G11*100)
I12: =H12-G12 | J12: =IF(G12=0,"",I12/G12*100)
I13: =H13-G13 | J13: =IF(G13=0,"",I13/G13*100)
I14: =H14-G14 | J14: =IF(G14=0,"",I14/G14*100)
I15: =H15-G15 | J15: =IF(G15=0,"",I15/G15*100)
I16: =H16-G16 | J16: =IF(G16=0,"",I16/G16*100)
I17: =H17-G17 | J17: =IF(G17=0,"",I17/G17*100)
... I25: =H25-G25 | J25: =IF(G25=0,"",I25/G25*100)
A26: 合计1 | B26: 合 计 | G26: =ROUND(SUM(G6:G25),2) | H26: =ROUND(SUM(H6:H25),2) | I26: =H26-G26 | J26: =IF(G26=0,"",I26/G26*100)
A27: 坏账准备 | B27: 减：应收票据坏账准备 | I27: =H27-G27 | J27: =IF(G27=0,"",I27/G27*100)
A28: 预计损失 | B28: 减：应收票据预计损失 | I28: =H28-G28 | J28: =IF(G28=0,"",I28/G28*100)
A29: 合计2 | B29: 合 计 | G29: =ROUND(G26-G27,2) | H29: =ROUND(H26-H28,2) | I29: =H29-G29 | J29: =IF(G29=0,"",I29/G29*100)

Sheet 3-5应收账款
A1: 表头区域 | B1: 应收账款评估明细表
A2: 表头区域 | B2: ='2-分类汇总'!B2
A3: 表头区域 | N3: 表3-5
A4: 表头区域 | B4: ='2-分类汇总'!B4 | N4: ='2-分类汇总'!H4
A5: 检索表头 | B5: 序号 | C5: 欠款单位名称（结算对象) | D5: 业务内容 | E5: 发生日期 | F5: 账龄 | G5: 币种 | H5: 外币账面金额 | I5: 评估基准日汇率 | J5: 账面价值 | K5: 评估价值 | L5: 增值额 | M5: 增值率% | N5: 备注
F6: =IF(E6="","",LOOKUP(DATEDIF(E6,评估基准日,"y"),公式数据表!$C$7:$C$10,公式数据表!$B$7:$B$10)) | L6: =K6-J6 | M6: =IF(J6=0,"",L6/J6*100)
F7: =IF(E7="","",LOOKUP(DATEDIF(E7,评估基准日,"y"),公式数据表!$C$7:$C$10,公式数据表!$B$7:$B$10)) | L7: =K7-J7 | M7: =IF(J7=0,"",L7/J7*100)
F8: =IF(E8="","",LOOKUP(DATEDIF(E8,评估基准日,"y"),公式数据表!$C$7:$C$10,公式数据表!$B$7:$B$10)) | L8: =K8-J8 | M8: =IF(J8=0,"",L8/J8*100)
F9: =IF(E9="","",LOOKUP(DATEDIF(E9,评估基准日,"y"),公式数据表!$C$7:$C$10,公式数据表!$B$7:$B$10)) | L9: =K9-J9 | M9: =IF(J9=0,"",L9/J9*100)
F10: =IF(E10="","",LOOKUP(DATEDIF(E10,评估基准日,"y"),公式数据表!$C$7:$C$10,公式数据表!$B$7:$B$10)) | L10: =K10-J10 | M10: =IF(J10=0,"",L10/J10*100)
F11: =IF(E11="","",LOOKUP(DATEDIF(E11,评估基准日,"y"),公式数据表!$C$7:$C$10,公式数据表!$B$7:$B$10)) | L11: =K11-J11 | M11: =IF(J11=0,"",L11/J11*100)
F12: =IF(E12="","",LOOKUP(DATEDIF(E12,评估基准日,"y"),公式数据表!$C$7:$C$10,公式数据表!$B$7:$B$10)) | L12: =K12-J12 | M12: =IF(J12=0,"",L12/J12*100)
F13: =IF(E13="","",LOOKUP(DATEDIF(E13,评估基准日,"y"),公式数据表!$C$7:$C$10,公式数据表!$B$7:$B$10)) | L13: =K13-J13 | M13: =IF(J13=0,"",L13/J13*100)
F14: =IF(E14="","",LOOKUP(DATEDIF(E14,评估基准日,"y"),公式数据表!$C$7:$C$10,公式数据表!$B$7:$B$10)) | L14: =K14-J14 | M14: =IF(J14=0,"",L14/J14*100)
F15: =IF(E15="","",LOOKUP(DATEDIF(E15,评估基准日,"y"),公式数据表!$C$7:$C$10,公式数据表!$B$7:$B$10)) | L15: =K15-J15 | M15: =IF(J15=0,"",L15/J15*100)
F16: =IF(E16="","",LOOKUP(DATEDIF(E16,评估基准日,"y"),公式数据表!$C$7:$C$10,公式数据表!$B$7:$B$10)) | L16: =K16-J16 | M16: =IF(J16=0,"",L16/J16*100)
F17: =IF(E17="","",LOOKUP(DATEDIF(E17,评估基准日,"y"),公式数据表!$C$7:$C$10,公式数据表!$B$7:$B$10)) | L17: =K17-J17 | M17: =IF(J17=0,"",L17/J17*100)
... F25: =IF(E25="","",LOOKUP(DATEDIF(E25,评估基准日,"y"),公式数据表!$C$7:$C$10,公式数据表!$B$7:$B$10)) | L25: =K25-J25 | M25: =IF(J25=0,"",L25/J25*100)
A26: 合计1 | B26: 合 计 | H26: =ROUND(SUM(H6:H25),2) | J26: =ROUND(SUM(J6:J25),2) | K26: =ROUND(SUM(K6:K25),2) | L26: =K26-J26 | M26: =IF(J26=0,"",L26/J26*100)
A27: 坏账准备 | B27: 减：应收账款坏账准备 | L27: =K27-J27 | M27: =IF(J27=0,"",L27/J27*100)
A28: 预计损失 | B28: 减：应收账款预计损失 | L28: =K28-J28 | M28: =IF(J28=0,"",L28/J28*100)
A29: 合计2 | B29: 合 计 | H29: =ROUND(H26-H27,2) | J29: =ROUND(J26-J27,2) | K29: =ROUND(K26-K28,2) | L29: =K29-J29 | M29: =IF(J29=0,"",L29/J29*100)

Sheet 3-6应收款项融资
A1: 表头区域 | B1: 应收款项融资评估明细表
A2: 表头区域 | B2: ='2-分类汇总'!B2
A3: 表头区域 | N3: 表3-6
A4: 表头区域 | B4: ='2-分类汇总'!B4 | N4: ='2-分类汇总'!H4
A5: 检索表头 | B5: 序号 | C5: 欠款单位名称（结算对象) | D5: 业务内容 | E5: 发生日期 | F5: 账龄 | G5: 币种 | H5: 外币账面金额 | I5: 评估基准日汇率 | J5: 账面价值 | K5: 评估价值 | L5: 增值额 | M5: 增值率% | N5: 备注
F6: =IF(E6="","",LOOKUP(DATEDIF(E6,评估基准日,"y"),公式数据表!$C$7:$C$10,公式数据表!$B$7:$B$10)) | L6: =K6-J6 | M6: =IF(J6=0,"",L6/J6*100)
F7: =IF(E7="","",LOOKUP(DATEDIF(E7,评估基准日,"y"),公式数据表!$C$7:$C$10,公式数据表!$B$7:$B$10)) | L7: =K7-J7 | M7: =IF(J7=0,"",L7/J7*100)
F8: =IF(E8="","",LOOKUP(DATEDIF(E8,评估基准日,"y"),公式数据表!$C$7:$C$10,公式数据表!$B$7:$B$10)) | L8: =K8-J8 | M8: =IF(J8=0,"",L8/J8*100)
F9: =IF(E9="","",LOOKUP(DATEDIF(E9,评估基准日,"y"),公式数据表!$C$7:$C$10,公式数据表!$B$7:$B$10)) | L9: =K9-J9 | M9: =IF(J9=0,"",L9/J9*100)
F10: =IF(E10="","",LOOKUP(DATEDIF(E10,评估基准日,"y"),公式数据表!$C$7:$C$10,公式数据表!$B$7:$B$10)) | L10: =K10-J10 | M10: =IF(J10=0,"",L10/J10*100)
F11: =IF(E11="","",LOOKUP(DATEDIF(E11,评估基准日,"y"),公式数据表!$C$7:$C$10,公式数据表!$B$7:$B$10)) | L11: =K11-J11 | M11: =IF(J11=0,"",L11/J11*100)
F12: =IF(E12="","",LOOKUP(DATEDIF(E12,评估基准日,"y"),公式数据表!$C$7:$C$10,公式数据表!$B$7:$B$10)) | L12: =K12-J12 | M12: =IF(J12=0,"",L12/J12*100)
F13: =IF(E13="","",LOOKUP(DATEDIF(E13,评估基准日,"y"),公式数据表!$C$7:$C$10,公式数据表!$B$7:$B$10)) | L13: =K13-J13 | M13: =IF(J13=0,"",L13/J13*100)
F14: =IF(E14="","",LOOKUP(DATEDIF(E14,评估基准日,"y"),公式数据表!$C$7:$C$10,公式数据表!$B$7:$B$10)) | L14: =K14-J14 | M14: =IF(J14=0,"",L14/J14*100)
F15: =IF(E15="","",LOOKUP(DATEDIF(E15,评估基准日,"y"),公式数据表!$C$7:$C$10,公式数据表!$B$7:$B$10)) | L15: =K15-J15 | M15: =IF(J15=0,"",L15/J15*100)
F16: =IF(E16="","",LOOKUP(DATEDIF(E16,评估基准日,"y"),公式数据表!$C$7:$C$10,公式数据表!$B$7:$B$10)) | L16: =K16-J16 | M16: =IF(J16=0,"",L16/J16*100)
F17: =IF(E17="","",LOOKUP(DATEDIF(E17,评估基准日,"y"),公式数据表!$C$7:$C$10,公式数据表!$B$7:$B$10)) | L17: =K17-J17 | M17: =IF(J17=0,"",L17/J17*100)
... F25: =IF(E25="","",LOOKUP(DATEDIF(E25,评估基准日,"y"),公式数据表!$C$7:$C$10,公式数据表!$B$7:$B$10)) | L25: =K25-J25 | M25: =IF(J25=0,"",L25/J25*100)
A26: 合计1 | B26: 合 计 | H26: =ROUND(SUM(H6:H25),2) | J26: =ROUND(SUM(J6:J25),2) | K26: =ROUND(SUM(K6:K25),2) | L26: =K26-J26 | M26: =IF(J26=0,"",L26/J26*100)
A27: 坏账准备 | B27: 减：应收账款坏账准备 | L27: =K27-J27 | M27: =IF(J27=0,"",L27/J27*100)
A28: 预计损失 | B28: 减：应收账款预计损失 | L28: =K28-J28 | M28: =IF(J28=0,"",L28/J28*100)
A29: 合计2 | B29: 合 计 | H29: =ROUND(H26-H27,2) | J29: =ROUND(J26-J27,2) | K29: =ROUND(K26-K28,2) | L29: =K29-J29 | M29: =IF(J29=0,"",L29/J29*100)

Sheet 3-7预付款项
A1: 表头区域 | B1: 预付款项评估明细表
A2: 表头区域 | B2: ='2-分类汇总'!B2
A3: 表头区域 | N3: 表3-7
A4: 表头区域 | B4: ='2-分类汇总'!B4 | N4: ='2-分类汇总'!H4
A5: 检索表头 | B5: 序号 | C5: 收款单位名称（结算对象) | D5: 业务内容 | E5: 发生日期 | F5: 账龄 | G5: 币种 | H5: 外币账面金额 | I5: 评估基准日汇率 | J5: 账面价值 | K5: 评估价值 | L5: 增值额 | M5: 增值率% | N5: 备注
F6: =IF(E6="","",LOOKUP(DATEDIF(E6,评估基准日,"y"),公式数据表!$C$7:$C$10,公式数据表!$B$7:$B$10)) | L6: =K6-J6 | M6: =IF(J6=0,"",L6/J6*100)
F7: =IF(E7="","",LOOKUP(DATEDIF(E7,评估基准日,"y"),公式数据表!$C$7:$C$10,公式数据表!$B$7:$B$10)) | L7: =K7-J7 | M7: =IF(J7=0,"",L7/J7*100)
F8: =IF(E8="","",LOOKUP(DATEDIF(E8,评估基准日,"y"),公式数据表!$C$7:$C$10,公式数据表!$B$7:$B$10)) | L8: =K8-J8 | M8: =IF(J8=0,"",L8/J8*100)
F9: =IF(E9="","",LOOKUP(DATEDIF(E9,评估基准日,"y"),公式数据表!$C$7:$C$10,公式数据表!$B$7:$B$10)) | L9: =K9-J9 | M9: =IF(J9=0,"",L9/J9*100)
F10: =IF(E10="","",LOOKUP(DATEDIF(E10,评估基准日,"y"),公式数据表!$C$7:$C$10,公式数据表!$B$7:$B$10)) | L10: =K10-J10 | M10: =IF(J10=0,"",L10/J10*100)
F11: =IF(E11="","",LOOKUP(DATEDIF(E11,评估基准日,"y"),公式数据表!$C$7:$C$10,公式数据表!$B$7:$B$10)) | L11: =K11-J11 | M11: =IF(J11=0,"",L11/J11*100)
F12: =IF(E12="","",LOOKUP(DATEDIF(E12,评估基准日,"y"),公式数据表!$C$7:$C$10,公式数据表!$B$7:$B$10)) | L12: =K12-J12 | M12: =IF(J12=0,"",L12/J12*100)
F13: =IF(E13="","",LOOKUP(DATEDIF(E13,评估基准日,"y"),公式数据表!$C$7:$C$10,公式数据表!$B$7:$B$10)) | L13: =K13-J13 | M13: =IF(J13=0,"",L13/J13*100)
F14: =IF(E14="","",LOOKUP(DATEDIF(E14,评估基准日,"y"),公式数据表!$C$7:$C$10,公式数据表!$B$7:$B$10)) | L14: =K14-J14 | M14: =IF(J14=0,"",L14/J14*100)
F15: =IF(E15="","",LOOKUP(DATEDIF(E15,评估基准日,"y"),公式数据表!$C$7:$C$10,公式数据表!$B$7:$B$10)) | L15: =K15-J15 | M15: =IF(J15=0,"",L15/J15*100)
F16: =IF(E16="","",LOOKUP(DATEDIF(E16,评估基准日,"y"),公式数据表!$C$7:$C$10,公式数据表!$B$7:$B$10)) | L16: =K16-J16 | M16: =IF(J16=0,"",L16/J16*100)
F17: =IF(E17="","",LOOKUP(DATEDIF(E17,评估基准日,"y"),公式数据表!$C$7:$C$10,公式数据表!$B$7:$B$10)) | L17: =K17-J17 | M17: =IF(J17=0,"",L17/J17*100)
... F25: =IF(E25="","",LOOKUP(DATEDIF(E25,评估基准日,"y"),公式数据表!$C$7:$C$10,公式数据表!$B$7:$B$10)) | L25: =K25-J25 | M25: =IF(J25=0,"",L25/J25*100)
A26: 合计1 | B26: 合 计 | H26: =ROUND(SUM(H6:H25),2) | J26: =ROUND(SUM(J6:J25),2) | K26: =ROUND(SUM(K6:K25),2) | L26: =K26-J26 | M26: =IF(J26=0,"",L26/J26*100)
A27: 坏账准备 | B27: 减：预付款项坏账准备 | L27: =K27-J27 | M27: =IF(J27=0,"",L27/J27*100)
A28: 合计2 | B28: 合 计 | H28: =ROUND(SUM(H8:H27),2) | J28: =ROUND(J26-J27,2) | K28: =ROUND(K26-K27,2) | L28: =K28-J28 | M28: =IF(J28=0,"",L28/J28*100)

Sheet 3-8其他应收款汇总
B1: 其他应收款评估汇总表
B2: ='2-分类汇总'!B2
H3: 表3-8
B4: ='2-分类汇总'!B4 | H4: ='2-分类汇总'!H4
B5: 编码 | C5: 项目编号 | D5: 科目名称 | E5: 账面价值 | F5: 评估价值 | G5: 增值额 | H5: 增值率%
B6: 3-8-1 | C6: 应收利息 | D6: 其他应收款—应收利息 | E6: ='3-8-1应收利息'!H30 | F6: ='3-8-1应收利息'!I30 | G6: =F6-E6 | H6: =IF(E6=0,"",G6/E6*100)
B7: 3-8-2 | C7: 应收股利 | D7: 其他应收款—应收股利 | E7: ='3-8-2应收股利'!F30 | F7: ='3-8-2应收股利'!G30 | G7: =F7-E7 | H7: =IF(E7=0,"",G7/E7*100)
B8: 3-8-3 | C8: 其他应收 | D8: 其他应收款—其他应收款 | E8: ='3-8-3其他应收款'!J30 | F8: ='3-8-3其他应收款'!K30 | G8: =F8-E8 | H8: =IF(E8=0,"",G8/E8*100)
G10: =F10-E10 | H10: =IF(E10=0,"",G10/E10*100)
G11: =F11-E11 | H11: =IF(E11=0,"",G11/E11*100)
G12: =F12-E12 | H12: =IF(E12=0,"",G12/E12*100)
G13: =F13-E13 | H13: =IF(E13=0,"",G13/E13*100)
G14: =F14-E14 | H14: =IF(E14=0,"",G14/E14*100)
G15: =F15-E15 | H15: =IF(E15=0,"",G15/E15*100)
G16: =F16-E16 | H16: =IF(E16=0,"",G16/E16*100)
G17: =F17-E17 | H17: =IF(E17=0,"",G17/E17*100)
G18: =F18-E18 | H18: =IF(E18=0,"",G18/E18*100)
G19: =F19-E19 | H19: =IF(E19=0,"",G19/E19*100)
G20: =F20-E20 | H20: =IF(E20=0,"",G20/E20*100)
G21: =F21-E21 | H21: =IF(E21=0,"",G21/E21*100)
A25: 合计1 | C25: 其收净额 | D25: 合 计 | E25: =SUM(E6:E24) | F25: =SUM(F6:F24) | G25: =F25-E25 | H25: =IF(E25=0,"",G25/E25*100)

Sheet 3-8-1应收利息
A1: 表头区域 | B1: 其他应收款—应收利息评估明细表
A2: 表头区域 | B2: ='3-8其他应收款汇总'!B2:H2
A3: 表头区域 | L3: 表3-8-1
A4: 表头区域 | B4: ='3-8其他应收款汇总'!B4 | L4: ='2-分类汇总'!H4
A5: 检索表头 | B5: 序号 | C5: 欠款单位名称（结算对象) | D5: 发生日期 | E5: 本金 | F5: 利息所属期间 | G5: 年利息率% | H5: 账面价值 | I5: 评估价值 | J5: 增值额 | K5: 增值率% | L5: 备注
J6: =I6-H6 | K6: =IF(H6=0,"",J6/H6*100)
J7: =I7-H7 | K7: =IF(H7=0,"",J7/H7*100)
J8: =I8-H8 | K8: =IF(H8=0,"",J8/H8*100)
J9: =I9-H9 | K9: =IF(H9=0,"",J9/H9*100)
J10: =I10-H10 | K10: =IF(H10=0,"",J10/H10*100)
J11: =I11-H11 | K11: =IF(H11=0,"",J11/H11*100)
J12: =I12-H12 | K12: =IF(H12=0,"",J12/H12*100)
J13: =I13-H13 | K13: =IF(H13=0,"",J13/H13*100)
J14: =I14-H14 | K14: =IF(H14=0,"",J14/H14*100)
J15: =I15-H15 | K15: =IF(H15=0,"",J15/H15*100)
J16: =I16-H16 | K16: =IF(H16=0,"",J16/H16*100)
J17: =I17-H17 | K17: =IF(H17=0,"",J17/H17*100)
... J29: =I29-H29 | K29: =IF(H29=0,"",J29/H29*100)
A30: 合计1 | B30: 合 计 | E30: =ROUND(SUM(E6:E29),2) | H30: =ROUND(SUM(H6:H29),2) | I30: =ROUND(SUM(I6:I29),2) | J30: =I30-H30 | K30: =IF(H30=0,"",J30/H30*100)

Sheet 3-8-2应收股利
A1: 表头区域 | B1: 其他应收款—应收股利评估明细表
A2: 表头区域 | B2: ='3-8其他应收款汇总'!B2:H2
A3: 表头区域 | J3: 表3-8-2
A4: 表头区域 | B4: ='3-8其他应收款汇总'!B4 | J4: ='2-分类汇总'!H4
A5: 检索表头 | B5: 序号 | C5: 户名（结算对象) | D5: 发生日期 | E5: 股利（利润）所属期间 | F5: 账面价值 | G5: 评估价值 | H5: 增值额 | I5: 增值率% | J5: 备注
H6: =G6-F6 | I6: =IF(F6=0,"",H6/F6*100)
H7: =G7-F7 | I7: =IF(F7=0,"",H7/F7*100)
H8: =G8-F8 | I8: =IF(F8=0,"",H8/F8*100)
H9: =G9-F9 | I9: =IF(F9=0,"",H9/F9*100)
H10: =G10-F10 | I10: =IF(F10=0,"",H10/F10*100)
H11: =G11-F11 | I11: =IF(F11=0,"",H11/F11*100)
H12: =G12-F12 | I12: =IF(F12=0,"",H12/F12*100)
H13: =G13-F13 | I13: =IF(F13=0,"",H13/F13*100)
H14: =G14-F14 | I14: =IF(F14=0,"",H14/F14*100)
H15: =G15-F15 | I15: =IF(F15=0,"",H15/F15*100)
H16: =G16-F16 | I16: =IF(F16=0,"",H16/F16*100)
H17: =G17-F17 | I17: =IF(F17=0,"",H17/F17*100)
... H29: =G29-F29 | I29: =IF(F29=0,"",H29/F29*100)
A30: 合计1 | B30: 合 计 | F30: =ROUND(SUM(F6:F29),2) | G30: =ROUND(SUM(G6:G29),2) | H30: =G30-F30 | I30: =IF(F30=0,"",H30/F30*100)

Sheet 3-8-3其他应收款
A1: 表头区域 | B1: 其他应收款—其他应收款评估明细表
A2: 表头区域 | B2: ='2-分类汇总'!B2
A3: 表头区域 | N3: 表3-8-3
A4: 表头区域 | B4: ='2-分类汇总'!B4 | N4: ='2-分类汇总'!H4
A5: 检索表头 | B5: 序号 | C5: 欠款单位（人）名称（结算对象) | D5: 业务内容 | E5: 发生日期 | F5: 账龄 | G5: 币种 | H5: 外币账面金额 | I5: 评估基准日汇率 | J5: 账面价值 | K5: 评估价值 | L5: 增值额 | M5: 增值率% | N5: 备注
F6: =IF(E6="","",LOOKUP(DATEDIF(E6,评估基准日,"y"),公式数据表!$C$7:$C$10,公式数据表!$B$7:$B$10)) | L6: =K6-J6 | M6: =IF(J6=0,"",L6/J6*100)
F7: =IF(E7="","",LOOKUP(DATEDIF(E7,评估基准日,"y"),公式数据表!$C$7:$C$10,公式数据表!$B$7:$B$10)) | L7: =K7-J7 | M7: =IF(J7=0,"",L7/J7*100)
F8: =IF(E8="","",LOOKUP(DATEDIF(E8,评估基准日,"y"),公式数据表!$C$7:$C$10,公式数据表!$B$7:$B$10)) | L8: =K8-J8 | M8: =IF(J8=0,"",L8/J8*100)
F9: =IF(E9="","",LOOKUP(DATEDIF(E9,评估基准日,"y"),公式数据表!$C$7:$C$10,公式数据表!$B$7:$B$10)) | L9: =K9-J9 | M9: =IF(J9=0,"",L9/J9*100)
F10: =IF(E10="","",LOOKUP(DATEDIF(E10,评估基准日,"y"),公式数据表!$C$7:$C$10,公式数据表!$B$7:$B$10)) | L10: =K10-J10 | M10: =IF(J10=0,"",L10/J10*100)
F11: =IF(E11="","",LOOKUP(DATEDIF(E11,评估基准日,"y"),公式数据表!$C$7:$C$10,公式数据表!$B$7:$B$10)) | L11: =K11-J11 | M11: =IF(J11=0,"",L11/J11*100)
F12: =IF(E12="","",LOOKUP(DATEDIF(E12,评估基准日,"y"),公式数据表!$C$7:$C$10,公式数据表!$B$7:$B$10)) | L12: =K12-J12 | M12: =IF(J12=0,"",L12/J12*100)
F13: =IF(E13="","",LOOKUP(DATEDIF(E13,评估基准日,"y"),公式数据表!$C$7:$C$10,公式数据表!$B$7:$B$10)) | L13: =K13-J13 | M13: =IF(J13=0,"",L13/J13*100)
F14: =IF(E14="","",LOOKUP(DATEDIF(E14,评估基准日,"y"),公式数据表!$C$7:$C$10,公式数据表!$B$7:$B$10)) | L14: =K14-J14 | M14: =IF(J14=0,"",L14/J14*100)
F15: =IF(E15="","",LOOKUP(DATEDIF(E15,评估基准日,"y"),公式数据表!$C$7:$C$10,公式数据表!$B$7:$B$10)) | L15: =K15-J15 | M15: =IF(J15=0,"",L15/J15*100)
F16: =IF(E16="","",LOOKUP(DATEDIF(E16,评估基准日,"y"),公式数据表!$C$7:$C$10,公式数据表!$B$7:$B$10)) | L16: =K16-J16 | M16: =IF(J16=0,"",L16/J16*100)
F17: =IF(E17="","",LOOKUP(DATEDIF(E17,评估基准日,"y"),公式数据表!$C$7:$C$10,公式数据表!$B$7:$B$10)) | L17: =K17-J17 | M17: =IF(J17=0,"",L17/J17*100)
... F26: =IF(E26="","",LOOKUP(DATEDIF(E26,评估基准日,"y"),公式数据表!$C$7:$C$10,公式数据表!$B$7:$B$10)) | L26: =K26-J26 | M26: =IF(J26=0,"",L26/J26*100)
A27: 合计1 | B27: 合 计 | H27: =ROUND(SUM(H6:H26),2) | J27: =ROUND(SUM(J6:J26),2) | K27: =ROUND(SUM(K6:K26),2) | L27: =K27-J27 | M27: =IF(J27=0,"",L27/J27*100)
A28: 坏账准备 | B28: 减：其他应收款坏账准备 | L28: =K28-J28 | M28: =IF(J28=0,"",L28/J28*100)
A29: 预计损失 | B29: 减：其他应收款预计损失 | L29: =K29-J29 | M29: =IF(J29=0,"",L29/J29*100)
A30: 合计2 | B30: 合 计 | H30: =ROUND(H27-H28,2) | J30: =ROUND(J27-J28,2) | K30: =ROUND(K27-K29,2) | L30: =K30-J30 | M30: =IF(J30=0,"",L30/J30*100)

Sheet 3-辅-流动资产汇总
A1: 流动资产余额评估汇总表
A2: ='2-分类汇总'!B2
G3: 表3
A4: ='2-分类汇总'!B4 | G4: ='2-分类汇总'!H4
A5: 编号 | B5: 项目编号 | C5: 科目名称 | D5: 账面价值 | E5: 评估价值 | F5: 增值额 | G5: 增值率%
A6: 3-4-1 | B6: 应票余额 | C6: 应收票据余额 | D6: ='3-4应收票据'!G26 | E6: ='3-4应收票据'!H26 | F6: =E6-D6 | G6: =IF(D6=0,"",F6/D6*100)
A7: 3-5-1 | B7: 应收余额 | C7: 应收账款余额 | D7: ='3-5应收账款'!J26 | E7: ='3-5应收账款'!K26 | F7: =E7-D7 | G7: =IF(D7=0,"",F7/D7*100)
A8: 3-6-1 | B8: 应融余额 | C8: 应收款项融资 | D8: ='3-6应收款项融资'!J26 | E8: ='3-6应收款项融资'!K26 | F8: =E8-D8 | G8: =IF(D8=0,"",F8/D8*100)
A9: 3-7-1 | B9: 预付余额 | C9: 预付账款余额 | D9: ='3-7预付款项'!J26 | E9: ='3-7预付款项'!K26 | F9: =E9-D9 | G9: =IF(D9=0,"",F9/D9*100)
A10: 3-8-1 | B10: 他收余额 | C10: 其他应收款余额 | D10: ='3-8-3其他应收款'!J27 | E10: ='3-8-3其他应收款'!K27 | F10: =E10-D10 | G10: =IF(D10=0,"",F10/D10*100)
A11: 3-9-1 | B11: 存货采购 | C11: 在途物资余额 | D11: ='3-9-1在途物资'!G26 | E11: ='3-9-1在途物资'!J26 | F11: =E11-D11 | G11: =IF(D11=0,"",F11/D11*100)
A12: 3-9-2 | B12: 存货原材 | C12: 原材料余额 | D12: ='3-9-2原材料'!H26 | E12: ='3-9-2原材料'!K26 | F12: =E12-D12 | G12: =IF(D12=0,"",F12/D12*100)
A13: 3-9-3 | B13: 存货在库 | C13: 在库周转材料余额 | D13: ='3-9-3在库周转材料'!H26 | E13: ='3-9-3在库周转材料'!K26 | F13: =E13-D13 | G13: =IF(D13=0,"",F13/D13*100)
A14: 3-9-4 | B14: 存货委加 | C14: 委托加工物资余额 | D14: ='3-9-4委托加工物资'!H26 | E14: ='3-9-4委托加工物资'!K26 | F14: =E14-D14 | G14: =IF(D14=0,"",F14/D14*100)
A15: 3-9-5 | B15: 存货产成 | C15: 产成品（库存商品）余额 | D15: ='3-9-5产成品（库存商品）'!H26 | E15: ='3-9-5产成品（库存商品）'!L26 | F15: =E15-D15 | G15: =IF(D15=0,"",F15/D15*100)
A16: 3-9-6 | B16: 存货在产 | C16: 在产品（自制半成品）余额 | D16: ='3-9-6在产品（自制半成品）'!H26 | E16: ='3-9-6在产品（自制半成品）'!K26 | F16: =E16-D16 | G16: =IF(D16=0,"",F16/D16*100)
A17: 3-9-7 | B17: 存货发出 | C17: 发出商品余额 | D17: ='3-9-7发出商品'!H26 | E17: ='3-9-7发出商品'!K26 | F17: =E17-D17 | G17: =IF(D17=0,"",F17/D17*100)
A18: 3-9-8 | B18: 存货在用 | C18: 在用周转材料余额 | D18: ='3-9-8在用周转材料'!H26 | E18: ='3-9-8在用周转材料'!L26 | F18: =E18-D18 | G18: =IF(D18=0,"",F18/D18*100)
A19: 3-9-9 | B19: 存货履约 | C19: 合同履约成本余额 | D19: ='3-9-9合同履约成本'!E26 | E19: ='3-9-9合同履约成本'!F26 | F19: =E19-D19 | G19: =IF(D19=0,"",F19/D19*100)
A20: 3-10-1 | B20: 合同余额 | C20: 合同资产余额 | D20: ='3-10合同资产'!F26 | E20: ='3-10合同资产'!G26 | F20: =E20-D20 | G20: =IF(D20=0,"",F20/D20*100)
B25: 流余汇总 | C25: 合计 | D25: =SUM(D6:D24) | E25: =SUM(E6:E24) | F25: =E25-D25 | G25: =IF(D25=0,"",F25/D25*100)

Sheet 3-9-辅-存货汇总
A1: 存货评估汇总表
A2: ='2-分类汇总'!B2
I3: 表3-9
A4: ='2-分类汇总'!B4 | I4: ='2-分类汇总'!H4
A5: 编号 | B5: 项目编号 | C5: 科目名称 | D5: 账面余额 | E5: 存货跌价准备 | F5: 账面价值 | G5: 评估价值 | H5: 增值额 | I5: 增值率%
A6: 3-9-1 | B6: 存货采购 | C6: 在途物资 | D6: ='3-9-1在途物资'!G26 | E6: ='3-9-1在途物资'!G27 | F6: ='3-9-1在途物资'!G28 | G6: ='3-9-1在途物资'!J28 | H6: =G6-F6 | I6: =IF(F6=0,"",H6/F6*100)
A7: 3-9-2 | B7: 存货原材 | C7: 原材料 | D7: ='3-9-2原材料'!H26 | E7: ='3-9-2原材料'!H27 | F7: ='3-9-2原材料'!H28 | G7: ='3-9-2原材料'!K28 | H7: =G7-F7 | I7: =IF(F7=0,"",H7/F7*100)
A8: 3-9-3 | B8: 存货在库 | C8: 在库周转材料 | D8: ='3-9-3在库周转材料'!H26 | E8: ='3-9-3在库周转材料'!H27 | F8: ='3-9-3在库周转材料'!H28 | G8: ='3-9-3在库周转材料'!K28 | H8: =G8-F8 | I8: =IF(F8=0,"",H8/F8*100)
A9: 3-9-4 | B9: 存货委加 | C9: 委托加工物资 | D9: ='3-9-4委托加工物资'!H26 | E9: ='3-9-4委托加工物资'!H27 | F9: ='3-9-4委托加工物资'!H28 | G9: ='3-9-4委托加工物资'!K28 | H9: =G9-F9 | I9: =IF(F9=0,"",H9/F9*100)
A10: 3-9-5 | B10: 存货产成 | C10: 产成品（库存商品） | D10: ='3-9-5产成品（库存商品）'!H26 | E10: ='3-9-5产成品（库存商品）'!H27 | F10: ='3-9-5产成品（库存商品）'!H28 | G10: ='3-9-5产成品（库存商品）'!L28 | H10: =G10-F10 | I10: =IF(F10=0,"",H10/F10*100)
A11: 3-9-6 | B11: 存货在产 | C11: 在产品（自制半成品） | D11: ='3-9-6在产品（自制半成品）'!H26 | E11: ='3-9-6在产品（自制半成品）'!H27 | F11: ='3-9-6在产品（自制半成品）'!H28 | G11: ='3-9-6在产品（自制半成品）'!K28 | H11: =G11-F11 | I11: =IF(F11=0,"",H11/F11*100)
A12: 3-9-7 | B12: 存货发出 | C12: 发出商品 | D12: ='3-9-7发出商品'!H26 | E12: ='3-9-7发出商品'!H27 | F12: ='3-9-7发出商品'!H28 | G12: ='3-9-7发出商品'!K28 | H12: =G12-F12 | I12: =IF(F12=0,"",H12/F12*100)
A13: 3-9-8 | B13: 存货在用 | C13: 在用周转材料 | D13: ='3-9-8在用周转材料'!H26 | E13: ='3-9-8在用周转材料'!H27 | F13: ='3-9-8在用周转材料'!H28 | G13: ='3-9-8在用周转材料'!L28 | H13: =G13-F13 | I13: =IF(F13=0,"",H13/F13*100)
A14: 3-9-9 | B14: 存货履约 | C14: 合同履约成本 | D14: ='3-9-9合同履约成本'!E26 | E14: ='3-9-9合同履约成本'!E27 | F14: ='3-9-9合同履约成本'!E28 | G14: ='3-9-9合同履约成本'!F28 | H14: =G14-F14 | I14: =IF(F14=0,"",H14/F14*100)
B23: 存货净额 | C23: 合 计 | D23: =SUM(D6:D14) | E23: =SUM(E6:E14) | F23: =SUM(F6:F14) | G23: =SUM(G6:G14) | H23: =G23-F23 | I23: =IF(F23=0,"",H23/F23*100)
A33: 3-9-1 | B33: 采购跌价 | C33: 材料采购（在途物资） | F33: ='3-9-1在途物资'!G27 | G33: ='3-9-1在途物资'!J27
A34: 3-9-2 | B34: 原材跌价 | C34: 原材料 | F34: ='3-9-2原材料'!H27 | G34: ='3-9-2原材料'!K27
A35: 3-9-3 | B35: 在库跌价 | C35: 在库周转材料 | F35: ='3-9-3在库周转材料'!H27 | G35: ='3-9-3在库周转材料'!K27
A36: 3-9-4 | B36: 委加跌价 | C36: 委托加工物资 | F36: ='3-9-4委托加工物资'!H27 | G36: ='3-9-4委托加工物资'!K27
A37: 3-9-5 | B37: 产成跌价 | C37: 产成品（库存商品） | F37: ='3-9-5产成品（库存商品）'!H27 | G37: ='3-9-5产成品（库存商品）'!L27
A38: 3-9-6 | B38: 在产跌价 | C38: 在产品（自制半成品） | F38: ='3-9-6在产品（自制半成品）'!H27 | G38: ='3-9-6在产品（自制半成品）'!K27
A39: 3-9-7 | B39: 发出跌价 | C39: 发出商品 | F39: ='3-9-7发出商品'!H27 | G39: ='3-9-7发出商品'!K27
A40: 3-9-8 | B40: 在用跌价 | C40: 在用周转材料 | F40: ='3-9-8在用周转材料'!H27 | G40: ='3-9-8在用周转材料'!L27

Sheet 3-9存货汇总
B1: 存货评估汇总表
B2: ='2-分类汇总'!B2
H3: 表3-9
B4: ='2-分类汇总'!B4 | H4: ='2-分类汇总'!H4
B5: 编号 | C5: 项目编号 | D5: 科目名称 | E5: 账面价值 | F5: 评估价值 | G5: 增值额 | H5: 增值率%
B6: 3-9-1 | C6: 存货采购 | D6: 在途物资 | E6: ='3-9-1在途物资'!G28 | F6: ='3-9-1在途物资'!J28 | G6: =F6-E6 | H6: =IF(E6=0,"",G6/E6*100)
B7: 3-9-2 | C7: 存货原材 | D7: 原材料 | E7: ='3-9-2原材料'!H28 | F7: ='3-9-2原材料'!K28 | G7: =F7-E7 | H7: =IF(E7=0,"",G7/E7*100)
B8: 3-9-3 | C8: 存货在库 | D8: 在库周转材料 | E8: ='3-9-3在库周转材料'!H28 | F8: ='3-9-3在库周转材料'!K28 | G8: =F8-E8 | H8: =IF(E8=0,"",G8/E8*100)
B9: 3-9-4 | C9: 存货委加 | D9: 委托加工物资 | E9: ='3-9-4委托加工物资'!H28 | F9: ='3-9-4委托加工物资'!K28 | G9: =F9-E9 | H9: =IF(E9=0,"",G9/E9*100)
B10: 3-9-5 | C10: 存货产成 | D10: 产成品（库存商品） | E10: ='3-9-5产成品（库存商品）'!H28 | F10: ='3-9-5产成品（库存商品）'!L28 | G10: =F10-E10 | H10: =IF(E10=0,"",G10/E10*100)
B11: 3-9-6 | C11: 存货在产 | D11: 在产品（自制半成品） | E11: ='3-9-6在产品（自制半成品）'!H28 | F11: ='3-9-6在产品（自制半成品）'!K28 | G11: =F11-E11 | H11: =IF(E11=0,"",G11/E11*100)
B12: 3-9-7 | C12: 存货发出 | D12: 发出商品 | E12: ='3-9-7发出商品'!H28 | F12: ='3-9-7发出商品'!K28 | G12: =F12-E12 | H12: =IF(E12=0,"",G12/E12*100)
B13: 3-9-8 | C13: 存货在用 | D13: 在用周转材料 | E13: ='3-9-8在用周转材料'!H28 | F13: ='3-9-8在用周转材料'!L28 | G13: =F13-E13 | H13: =IF(E13=0,"",G13/E13*100)
B14: 3-9-9 | C14: 存货履约 | D14: 合同履约成本 | E14: ='3-9-9合同履约成本'!E28 | F14: ='3-9-9合同履约成本'!F28 | G14: =F14-E14 | H14: =IF(E14=0,"",G14/E14*100)
A23: 合计1 | C23: 存货净额 | D23: 合 计 | E23: =SUM(E6:E14) | F23: =SUM(F6:F14) | G23: =F23-E23 | H23: =IF(E23=0,"",G23/E23*100)

Sheet 3-9-1在途物资
A1: 表头区域 | B1: 存货—在途物资评估明细表
A2: 表头区域 | B2: ='2-分类汇总'!B2
A3: 表头区域 | M3: 表3-9-1
A4: 表头区域 | B4: ='2-分类汇总'!B4 | M4: ='2-分类汇总'!H4
A5: 检索表头1 | B5: 序号 | C5: 名称及规格型号 | D5: 计量单位 | E5: 账面价值 | H5: 评估价值 | K5: 增值额 | L5: 增值率% | M5: 备注
A6: 检索表头2 | E6: 数量 | F6: 单价 | G6: 金额 | H6: 实际数量 | I6: 评估单价 | J6: 金额
K7: =J7-G7 | L7: =IF(G7=0,"",K7/G7*100)
K8: =J8-G8 | L8: =IF(G8=0,"",K8/G8*100)
K9: =J9-G9 | L9: =IF(G9=0,"",K9/G9*100)
K10: =J10-G10 | L10: =IF(G10=0,"",K10/G10*100)
K11: =J11-G11 | L11: =IF(G11=0,"",K11/G11*100)
K12: =J12-G12 | L12: =IF(G12=0,"",K12/G12*100)
K13: =J13-G13 | L13: =IF(G13=0,"",K13/G13*100)
K14: =J14-G14 | L14: =IF(G14=0,"",K14/G14*100)
K15: =J15-G15 | L15: =IF(G15=0,"",K15/G15*100)
K16: =J16-G16 | L16: =IF(G16=0,"",K16/G16*100)
K17: =J17-G17 | L17: =IF(G17=0,"",K17/G17*100)
K18: =J18-G18 | L18: =IF(G18=0,"",K18/G18*100)
... K25: =J25-G25 | L25: =IF(G25=0,"",K25/G25*100)
A26: 合计1 | B26: 合 计 | E26: =ROUND(SUM(E7:E25),2) | G26: =ROUND(SUM(G7:G25),2) | H26: =ROUND(SUM(H7:H25),2) | J26: =ROUND(SUM(J7:J25),2) | K26: =J26-G26 | L26: =IF(G26=0,"",K26/G26*100)
A27: 坏账准备 | B27: 减：存货跌价准备 | K27: =J27-G27 | L27: =IF(G27=0,"",K27/G27*100)
A28: 合计2 | B28: 合 计 | E28: =ROUND(E26-E27,2) | G28: =ROUND(G26-G27,2) | H28: =ROUND(H26-H27,2) | J28: =ROUND(J26-J27,2) | K28: =J28-G28 | L28: =IF(G28=0,"",K28/G28*100)

Sheet 3-9-2原材料
A1: 表头区域 | B1: 存货—原材料评估明细表
A2: 表头区域 | B2: ='2-分类汇总'!B2
A3: 表头区域 | N3: 表3-9-2
A4: 表头区域 | B4: ='2-分类汇总'!B4 | N4: ='2-分类汇总'!H4
A5: 检索表头1 | B5: 序号 | C5: 名称及规格型号 | D5: 计量单位 | E5: 存放地点 | F5: 账面价值 | I5: 评估价值 | L5: 增值额 | M5: 增值率% | N5: 备注
A6: 检索表头2 | F6: 数量 | G6: 单价 | H6: 金额 | I6: 实际数量 | J6: 评估单价 | K6: 金额
L7: =K7-H7 | M7: =IF(H7=0,"",L7/H7*100)
L8: =K8-H8 | M8: =IF(H8=0,"",L8/H8*100)
L9: =K9-H9 | M9: =IF(H9=0,"",L9/H9*100)
L10: =K10-H10 | M10: =IF(H10=0,"",L10/H10*100)
L11: =K11-H11 | M11: =IF(H11=0,"",L11/H11*100)
L12: =K12-H12 | M12: =IF(H12=0,"",L12/H12*100)
L13: =K13-H13 | M13: =IF(H13=0,"",L13/H13*100)
L14: =K14-H14 | M14: =IF(H14=0,"",L14/H14*100)
L15: =K15-H15 | M15: =IF(H15=0,"",L15/H15*100)
L16: =K16-H16 | M16: =IF(H16=0,"",L16/H16*100)
L17: =K17-H17 | M17: =IF(H17=0,"",L17/H17*100)
L18: =K18-H18 | M18: =IF(H18=0,"",L18/H18*100)
... L25: =K25-H25 | M25: =IF(H25=0,"",L25/H25*100)
A26: 合计1 | B26: 合 计 | F26: =ROUND(SUM(F7:F25),2) | H26: =ROUND(SUM(H7:H25),2) | I26: =ROUND(SUM(I7:I25),2) | K26: =ROUND(SUM(K7:K25),2) | L26: =K26-H26 | M26: =IF(H26=0,"",L26/H26*100)
A27: 坏账准备 | B27: 减：存货跌价准备 | L27: =K27-H27 | M27: =IF(H27=0,"",L27/H27*100)
A28: 合计2 | B28: 合 计 | F28: =ROUND(F26-F27,2) | H28: =ROUND(H26-H27,2) | I28: =ROUND(I26-I27,2) | K28: =ROUND(K26-K27,2) | L28: =K28-H28 | M28: =IF(H28=0,"",L28/H28*100)

Sheet 3-9-3在库周转材料
A1: 表头区域 | B1: 存货—在库周转材料评估明细表
A2: 表头区域 | B2: ='2-分类汇总'!B2
A3: 表头区域 | N3: 表3-9-3
A4: 表头区域 | B4: ='2-分类汇总'!B4 | N4: ='2-分类汇总'!H4
A5: 检索表头1 | B5: 序号 | C5: 名称及规格型号 | D5: 计量单位 | E5: 存放地点 | F5: 账面价值 | I5: 评估价值 | L5: 增值额 | M5: 增值率% | N5: 备注
A6: 检索表头2 | F6: 数量 | G6: 单价 | H6: 金额 | I6: 实际数量 | J6: 评估单价 | K6: 金额
L7: =K7-H7 | M7: =IF(H7=0,"",L7/H7*100)
L8: =K8-H8 | M8: =IF(H8=0,"",L8/H8*100)
L9: =K9-H9 | M9: =IF(H9=0,"",L9/H9*100)
L10: =K10-H10 | M10: =IF(H10=0,"",L10/H10*100)
L11: =K11-H11 | M11: =IF(H11=0,"",L11/H11*100)
L12: =K12-H12 | M12: =IF(H12=0,"",L12/H12*100)
L13: =K13-H13 | M13: =IF(H13=0,"",L13/H13*100)
L14: =K14-H14 | M14: =IF(H14=0,"",L14/H14*100)
L15: =K15-H15 | M15: =IF(H15=0,"",L15/H15*100)
L16: =K16-H16 | M16: =IF(H16=0,"",L16/H16*100)
L17: =K17-H17 | M17: =IF(H17=0,"",L17/H17*100)
L18: =K18-H18 | M18: =IF(H18=0,"",L18/H18*100)
... L25: =K25-H25 | M25: =IF(H25=0,"",L25/H25*100)
A26: 合计1 | B26: 合计 | F26: =ROUND(SUM(F7:F25),2) | H26: =ROUND(SUM(H7:H25),2) | I26: =ROUND(SUM(I7:I25),2) | K26: =ROUND(SUM(K7:K25),2) | L26: =K26-H26 | M26: =IF(H26=0,"",L26/H26*100)
A27: 坏账准备 | B27: 减：存货跌价准备 | L27: =K27-H27 | M27: =IF(H27=0,"",L27/H27*100)
A28: 合计2 | B28: 合计 | F28: =ROUND(F26-F27,2) | H28: =ROUND(H26-H27,2) | I28: =ROUND(I26-I27,2) | K28: =ROUND(K26-K27,2) | L28: =K28-H28 | M28: =IF(H28=0,"",L28/H28*100)

Sheet 3-9-4委托加工物资
A1: 表头区域 | B1: 存货—委托加工物资评估明细表
A2: 表头区域 | B2: ='2-分类汇总'!B2
A3: 表头区域 | M3: 表3-9-4
A4: 表头区域 | B4: ='2-分类汇总'!B4 | N4: ='2-分类汇总'!H4
A5: 检索表头1 | B5: 序号 | C5: 名称及规格型号 | D5: 加工单位名称 | E5: 计量单位 | F5: 账面价值 | I5: 评估价值 | L5: 增值额 | M5: 增值率% | N5: 备注
A6: 检索表头2 | F6: 数量 | G6: 单价 | H6: 金额 | I6: 实际数量 | J6: 评估单价 | K6: 金额
L7: =K7-H7 | M7: =IF(H7=0,"",L7/H7*100)
L8: =K8-H8 | M8: =IF(H8=0,"",L8/H8*100)
L9: =K9-H9 | M9: =IF(H9=0,"",L9/H9*100)
L10: =K10-H10 | M10: =IF(H10=0,"",L10/H10*100)
L11: =K11-H11 | M11: =IF(H11=0,"",L11/H11*100)
L12: =K12-H12 | M12: =IF(H12=0,"",L12/H12*100)
L13: =K13-H13 | M13: =IF(H13=0,"",L13/H13*100)
L14: =K14-H14 | M14: =IF(H14=0,"",L14/H14*100)
L15: =K15-H15 | M15: =IF(H15=0,"",L15/H15*100)
L16: =K16-H16 | M16: =IF(H16=0,"",L16/H16*100)
L17: =K17-H17 | M17: =IF(H17=0,"",L17/H17*100)
L18: =K18-H18 | M18: =IF(H18=0,"",L18/H18*100)
... L25: =K25-H25 | M25: =IF(H25=0,"",L25/H25*100)
